Workbook

Sheet Tổng hợp
A1: TỔNG HỢP BẢNG GIÁ – ĐỒNG TÂM KHU VỰC 23
A2: Loại | B2: Qui cách (mm) | C2: Mã SAP | D2: Tên SP nhà máy | E2: Tên SP (Mã Sap) | F2: Tên báo giá App | G2: Men | H2: Giỏ hàng | I2: Loại giá | J2: Giá lẻ (đ/m²) | K2: Giá ĐL Nhận kho (đ/m²) | L2: Giá ĐL Đi giao (đ/m²) | M2: Giá Sale Nhận kho (đ/m²) | N2: Giá Sale Đi giao (đ/m²) | O2: % Margin Nhận kho | P2: % Margin Đi giao | Q2: Ghi chú | R2: Giá CT150 Nhận kho (đ/m²) | S2: Giá CT150 Đi giao (đ/m²) | T2: % Margin CT150 nhận kho | U2: Tên hóa đơn | V2: Công năng | W2: Màu | X2: Tính năng | Y2: Hoa văn | Z2: Khối lượng tổng | AA2: Đơn vị tính | AB2: Chiều dài | AC2: Chiều rộng | AD2: Chiều cao | AE2: Đơn vị kích thước | AF2: Nhóm vật tư mở rộng | AG2: Mô tả nhóm vật tư | AH2: Phân loại sản phẩm mới
A3: PORCELAIN | B3: 1000x1000 | C3: 10003644 | D3: 41100DB038 | E3: POR 1000x1000, 100DB038, AA | F3: 100DB038 | G3: DOUBLE_CHARGE | H3: 2. Chủ lực | I3: ĐL | J3: 715000 | K3: 572000 | L3: 593000 | O3: 0.2 | P3: 0.17062937 | R3: 543400 | S3: 593000 | T3: 0.24 | U3: =IFERROR(_xlfn.XLOOKUP($C3,'Thông tin về sản phẩm'!$A$2:$A$6228,'Thông tin về sản phẩm'!$F$2:$F$6228),"") -> GẠCH, POR 1000x1000, 100DB038, Loại AA (L1) | V3: =IFERROR(_xlfn.XLOOKUP($C3,'Thông tin về sản phẩm'!$A$2:$A$6228,'Thông tin về sản phẩm'!$S$2:$S$6228),"") -> ỐP_LÁT | W3: =IFERROR(_xlfn.XLOOKUP($C3,'Thông tin về sản phẩm'!$A$2:$A$6228,'Thông tin về sản phẩm'!$Y$2:$Y$6228),"") -> KEM | X3: =IFERROR(_xlfn.XLOOKUP($C3,'Thông tin về sản phẩm'!$A$2:$A$6228,'Thông tin về sản phẩm'!$AA$2:$AA$6228),"") -> ĐẶC_THÙ | Y3: =IFERROR(_xlfn.XLOOKUP($C3,'Thông tin về sản phẩm'!$A$2:$A$6228,'Thông tin về sản phẩm'!$AC$2:$AC$6228),"") -> VÂN_ĐÁ | Z3: =IFERROR(_xlfn.XLOOKUP($C3,'Thông tin về sản phẩm'!$A$2:$A$6228,'Thông tin về sản phẩm'!$AD$2:$AD$6228),"") -> 25.5 | AA3: =IFERROR(_xlfn.XLOOKUP($C3,'Thông tin về sản phẩm'!$A$2:$A$6228,'Thông tin về sản phẩm'!$I$2:$I$6228),"") -> VIE | AB3: =IFERROR(_xlfn.XLOOKUP($C3,'Thông tin về sản phẩm'!$A$2:$A$6228,'Thông tin về sản phẩm'!$AI$2:$AI$6228),"") -> 1000 | AC3: =IFERROR(_xlfn.XLOOKUP($C3,'Thông tin về sản phẩm'!$A$2:$A$6228,'Thông tin về sản phẩm'!$AJ$2:$AJ$6228),"") -> 1000 | AD3: =IFERROR(_xlfn.XLOOKUP($C3,'Thông tin về sản phẩm'!$A$2:$A$6228,'Thông tin về sản phẩm'!$AK$2:$AK$6228),"") -> 11.5 | AE3: =IFERROR(_xlfn.XLOOKUP($C3,'Thông tin về sản phẩm'!$A$2:$A$6228,'Thông tin về sản phẩm'!$AL$2:$AL$6228),"") -> MM | AF3: =IFERROR(_xlfn.XLOOKUP($C3,'Thông tin về sản phẩm'!$A$2:$A$6228,'Thông tin về sản phẩm'!$AM$2:$AM$6228),"") -> MV | AG3: =IFERROR(_xlfn.XLOOKUP($C3,'Thông tin về sản phẩm'!$A$2:$A$6228,'Thông tin về sản phẩm'!$AY$2:$AY$6228),"") -> Gạch POR Ốp_Lát | AH3: =IFERROR(_xlfn.XLOOKUP($C3,'Thông tin về sản phẩm'!$A$2:$A$6228,'Thông tin về sản phẩm'!$AZ$2:$AZ$6228),"") -> 2. Chủ lực
A4: PORCELAIN | B4: 1000x1000 | C4: 10005894 | D4: 41100DONGVAN001-FP-H+ | E4: POR 1000x1000, 100DONGVAN001-FP-H+, AA | F4: 100DONGVAN001-FP-H+ | G4: FP | H4: 2. Chủ lực | I4: ĐL | J4: 562000 | K4: 450000 | L4: 466000 | O4: 0.19928826 | P4: 0.17081851 | R4: 427500 | S4: 466000 | T4: 0.23932384 | U4: =IFERROR(_xlfn.XLOOKUP($C4,'Thông tin về sản phẩm'!$A$2:$A$6228,'Thông tin về sản phẩm'!$F$2:$F$6228),"") -> GẠCH, POR 1000x1000, 100DONGVAN001-FP-H+, Loại AA (L1) | V4: =IFERROR(_xlfn.XLOOKUP($C4,'Thông tin về sản phẩm'!$A$2:$A$6228,'Thông tin về sản phẩm'!$S$2:$S$6228),"") -> ỐP_LÁT | W4: =IFERROR(_xlfn.XLOOKUP($C4,'Thông tin về sản phẩm'!$A$2:$A$6228,'Thông tin về sản phẩm'!$Y$2:$Y$6228),"") -> XÁM | X4: =IFERROR(_xlfn.XLOOKUP($C4,'Thông tin về sản phẩm'!$A$2:$A$6228,'Thông tin về sản phẩm'!$AA$2:$AA$6228),"") -> KHÁNG_KHUẨN | Y4: =IFERROR(_xlfn.XLOOKUP($C4,'Thông tin về sản phẩm'!$A$2:$A$6228,'Thông tin về sản phẩm'!$AC$2:$AC$6228),"") -> VÂN_ĐÁ_MARBLE_CẨM_THẠCH | Z4: =IFERROR(_xlfn.XLOOKUP($C4,'Thông tin về sản phẩm'!$A$2:$A$6228,'Thông tin về sản phẩm'!$AD$2:$AD$6228),"") -> 25.5 | AA4: =IFERROR(_xlfn.XLOOKUP($C4,'Thông tin về sản phẩm'!$A$2:$A$6228,'Thông tin về sản phẩm'!$I$2:$I$6228),"") -> VIE | AB4: =IFERROR(_xlfn.XLOOKUP($C4,'Thông tin về sản phẩm'!$A$2:$A$6228,'Thông tin về sản phẩm'!$AI$2:$AI$6228),"") -> 1000 | AC4: =IFERROR(_xlfn.XLOOKUP($C4,'Thông tin về sản phẩm'!$A$2:$A$6228,'Thông tin về sản phẩm'!$AJ$2:$AJ$6228),"") -> 1000 | AD4: =IFERROR(_xlfn.XLOOKUP($C4,'Thông tin về sản phẩm'!$A$2:$A$6228,'Thông tin về sản phẩm'!$AK$2:$AK$6228),"") -> 11.5 | AE4: =IFERROR(_xlfn.XLOOKUP($C4,'Thông tin về sản phẩm'!$A$2:$A$6228,'Thông tin về sản phẩm'!$AL$2:$AL$6228),"") -> MM | AF4: =IFERROR(_xlfn.XLOOKUP($C4,'Thông tin về sản phẩm'!$A$2:$A$6228,'Thông tin về sản phẩm'!$AM$2:$AM$6228),"") -> MX | AG4: =IFERROR(_xlfn.XLOOKUP($C4,'Thông tin về sản phẩm'!$A$2:$A$6228,'Thông tin về sản phẩm'!$AY$2:$AY$6228),"") -> Gạch POR Ốp_Lát | AH4: =IFERROR(_xlfn.XLOOKUP($C4,'Thông tin về sản phẩm'!$A$2:$A$6228,'Thông tin về sản phẩm'!$AZ$2:$AZ$6228),"") -> 2. Chủ lực
A5: PORCELAIN | B5: 1000x1000 | C5: 10005896 | D5: 41100DONGVAN002-FP-H+ | E5: POR 1000x1000, 100DONGVAN002-FP-H+, AA | F5: 100DONGVAN002-FP-H+ | G5: FP | H5: 2. Chủ lực | I5: ĐL | J5: 562000 | K5: 450000 | L5: 466000 | O5: 0.19928826 | P5: 0.17081851 | R5: 427500 | S5: 466000 | T5: 0.23932384 | U5: =IFERROR(_xlfn.XLOOKUP($C5,'Thông tin về sản phẩm'!$A$2:$A$6228,'Thông tin về sản phẩm'!$F$2:$F$6228),"") -> GẠCH, POR 1000x1000, 100DONGVAN002-FP-H+, Loại AA (L1) | V5: =IFERROR(_xlfn.XLOOKUP($C5,'Thông tin về sản phẩm'!$A$2:$A$6228,'Thông tin về sản phẩm'!$S$2:$S$6228),"") -> ỐP_LÁT | W5: =IFERROR(_xlfn.XLOOKUP($C5,'Thông tin về sản phẩm'!$A$2:$A$6228,'Thông tin về sản phẩm'!$Y$2:$Y$6228),"") -> KEM | X5: =IFERROR(_xlfn.XLOOKUP($C5,'Thông tin về sản phẩm'!$A$2:$A$6228,'Thông tin về sản phẩm'!$AA$2:$AA$6228),"") -> KHÁNG_KHUẨN | Y5: =IFERROR(_xlfn.XLOOKUP($C5,'Thông tin về sản phẩm'!$A$2:$A$6228,'Thông tin về sản phẩm'!$AC$2:$AC$6228),"") -> VÂN_ĐÁ_MARBLE_CẨM_THẠCH | Z5: =IFERROR(_xlfn.XLOOKUP($C5,'Thông tin về sản phẩm'!$A$2:$A$6228,'Thông tin về sản phẩm'!$AD$2:$AD$6228),"") -> 25.5 | AA5: =IFERROR(_xlfn.XLOOKUP($C5,'Thông tin về sản phẩm'!$A$2:$A$6228,'Thông tin về sản phẩm'!$I$2:$I$6228),"") -> VIE | AB5: =IFERROR(_xlfn.XLOOKUP($C5,'Thông tin về sản phẩm'!$A$2:$A$6228,'Thông tin về sản phẩm'!$AI$2:$AI$6228),"") -> 1000 | AC5: =IFERROR(_xlfn.XLOOKUP($C5,'Thông tin về sản phẩm'!$A$2:$A$6228,'Thông tin về sản phẩm'!$AJ$2:$AJ$6228),"") -> 1000 | AD5: =IFERROR(_xlfn.XLOOKUP($C5,'Thông tin về sản phẩm'!$A$2:$A$6228,'Thông tin về sản phẩm'!$AK$2:$AK$6228),"") -> 11.5 | AE5: =IFERROR(_xlfn.XLOOKUP($C5,'Thông tin về sản phẩm'!$A$2:$A$6228,'Thông tin về sản phẩm'!$AL$2:$AL$6228),"") -> MM | AF5: =IFERROR(_xlfn.XLOOKUP($C5,'Thông tin về sản phẩm'!$A$2:$A$6228,'Thông tin về sản phẩm'!$AM$2:$AM$6228),"") -> MV | AG5: =IFERROR(_xlfn.XLOOKUP($C5,'Thông tin về sản phẩm'!$A$2:$A$6228,'Thông tin về sản phẩm'!$AY$2:$AY$6228),"") -> Gạch POR Ốp_Lát | AH5: =IFERROR(_xlfn.XLOOKUP($C5,'Thông tin về sản phẩm'!$A$2:$A$6228,'Thông tin về sản phẩm'!$AZ$2:$AZ$6228),"") -> 2. Chủ lực
A6: PORCELAIN | B6: 1000x1000 | C6: 10005897 | D6: 41100DONGVAN003-FP-H+ | E6: POR 1000x1000, 100DONGVAN003-FP-H+, AA | F6: 100DONGVAN003-FP-H+ | G6: FP | H6: 2. Chủ lực | I6: ĐL | J6: 562000 | K6: 450000 | L6: 466000 | O6: 0.19928826 | P6: 0.17081851 | R6: 427500 | S6: 466000 | T6: 0.23932384 | U6: =IFERROR(_xlfn.XLOOKUP($C6,'Thông tin về sản phẩm'!$A$2:$A$6228,'Thông tin về sản phẩm'!$F$2:$F$6228),"") -> GẠCH, POR 1000x1000, 100DONGVAN003-FP-H+, Loại AA (L1) | V6: =IFERROR(_xlfn.XLOOKUP($C6,'Thông tin về sản phẩm'!$A$2:$A$6228,'Thông tin về sản phẩm'!$S$2:$S$6228),"") -> ỐP_LÁT | W6: =IFERROR(_xlfn.XLOOKUP($C6,'Thông tin về sản phẩm'!$A$2:$A$6228,'Thông tin về sản phẩm'!$Y$2:$Y$6228),"") -> KEM | X6: =IFERROR(_xlfn.XLOOKUP($C6,'Thông tin về sản phẩm'!$A$2:$A$6228,'Thông tin về sản phẩm'!$AA$2:$AA$6228),"") -> KHÁNG_KHUẨN | Y6: =IFERROR(_xlfn.XLOOKUP($C6,'Thông tin về sản phẩm'!$A$2:$A$6228,'Thông tin về sản phẩm'!$AC$2:$AC$6228),"") -> VÂN_ĐÁ | Z6: =IFERROR(_xlfn.XLOOKUP($C6,'Thông tin về sản phẩm'!$A$2:$A$6228,'Thông tin về sản phẩm'!$AD$2:$AD$6228),"") -> 25.5 | AA6: =IFERROR(_xlfn.XLOOKUP($C6,'Thông tin về sản phẩm'!$A$2:$A$6228,'Thông tin về sản phẩm'!$I$2:$I$6228),"") -> VIE | AB6: =IFERROR(_xlfn.XLOOKUP($C6,'Thông tin về sản phẩm'!$A$2:$A$6228,'Thông tin về sản phẩm'!$AI$2:$AI$6228),"") -> 1000 | AC6: =IFERROR(_xlfn.XLOOKUP($C6,'Thông tin về sản phẩm'!$A$2:$A$6228,'Thông tin về sản phẩm'!$AJ$2:$AJ$6228),"") -> 1000 | AD6: =IFERROR(_xlfn.XLOOKUP($C6,'Thông tin về sản phẩm'!$A$2:$A$6228,'Thông tin về sản phẩm'!$AK$2:$AK$6228),"") -> 11.5 | AE6: =IFERROR(_xlfn.XLOOKUP($C6,'Thông tin về sản phẩm'!$A$2:$A$6228,'Thông tin về sản phẩm'!$AL$2:$AL$6228),"") -> MM | AF6: =IFERROR(_xlfn.XLOOKUP($C6,'Thông tin về sản phẩm'!$A$2:$A$6228,'Thông tin về sản phẩm'!$AM$2:$AM$6228),"") -> MV | AG6: =IFERROR(_xlfn.XLOOKUP($C6,'Thông tin về sản phẩm'!$A$2:$A$6228,'Thông tin về sản phẩm'!$AY$2:$AY$6228),"") -> Gạch POR Ốp_Lát | AH6: =IFERROR(_xlfn.XLOOKUP($C6,'Thông tin về sản phẩm'!$A$2:$A$6228,'Thông tin về sản phẩm'!$AZ$2:$AZ$6228),"") -> 2. Chủ lực
A7: PORCELAIN | B7: 1000x1000 | C7: 10005898 | D7: 41100DONGVAN008-FP-H+ | E7: POR 1000x1000, 100DONGVAN008-FP-H+, AA | F7: 100DONGVAN008-FP-H+ | G7: FP | H7: 2. Chủ lực | I7: ĐL | J7: 562000 | K7: 450000 | L7: 466000 | O7: 0.19928826 | P7: 0.17081851 | R7: 427500 | S7: 466000 | T7: 0.23932384 | U7: =IFERROR(_xlfn.XLOOKUP($C7,'Thông tin về sản phẩm'!$A$2:$A$6228,'Thông tin về sản phẩm'!$F$2:$F$6228),"") -> GẠCH, POR 1000x1000, 100DONGVAN008-FP-H+, Loại AA (L1) | V7: =IFERROR(_xlfn.XLOOKUP($C7,'Thông tin về sản phẩm'!$A$2:$A$6228,'Thông tin về sản phẩm'!$S$2:$S$6228),"") -> ỐP_LÁT | W7: =IFERROR(_xlfn.XLOOKUP($C7,'Thông tin về sản phẩm'!$A$2:$A$6228,'Thông tin về sản phẩm'!$Y$2:$Y$6228),"") -> KEM | X7: =IFERROR(_xlfn.XLOOKUP($C7,'Thông tin về sản phẩm'!$A$2:$A$6228,'Thông tin về sản phẩm'!$AA$2:$AA$6228),"") -> KHÁNG_KHUẨN | Y7: =IFERROR(_xlfn.XLOOKUP($C7,'Thông tin về sản phẩm'!$A$2:$A$6228,'Thông tin về sản phẩm'!$AC$2:$AC$6228),"") -> VÂN_ĐÁ_MARBLE_CẨM_THẠCH | Z7: =IFERROR(_xlfn.XLOOKUP($C7,'Thông tin về sản phẩm'!$A$2:$A$6228,'Thông tin về sản phẩm'!$AD$2:$AD$6228),"") -> 25.5 | AA7: =IFERROR(_xlfn.XLOOKUP($C7,'Thông tin về sản phẩm'!$A$2:$A$6228,'Thông tin về sản phẩm'!$I$2:$I$6228),"") -> VIE | AB7: =IFERROR(_xlfn.XLOOKUP($C7,'Thông tin về sản phẩm'!$A$2:$A$6228,'Thông tin về sản phẩm'!$AI$2:$AI$6228),"") -> 1000 | AC7: =IFERROR(_xlfn.XLOOKUP($C7,'Thông tin về sản phẩm'!$A$2:$A$6228,'Thông tin về sản phẩm'!$AJ$2:$AJ$6228),"") -> 1000 | AD7: =IFERROR(_xlfn.XLOOKUP($C7,'Thông tin về sản phẩm'!$A$2:$A$6228,'Thông tin về sản phẩm'!$AK$2:$AK$6228),"") -> 11.5 | AE7: =IFERROR(_xlfn.XLOOKUP($C7,'Thông tin về sản phẩm'!$A$2:$A$6228,'Thông tin về sản phẩm'!$AL$2:$AL$6228),"") -> MM | AF7: =IFERROR(_xlfn.XLOOKUP($C7,'Thông tin về sản phẩm'!$A$2:$A$6228,'Thông tin về sản phẩm'!$AM$2:$AM$6228),"") -> MV | AG7: =IFERROR(_xlfn.XLOOKUP($C7,'Thông tin về sản phẩm'!$A$2:$A$6228,'Thông tin về sản phẩm'!$AY$2:$AY$6228),"") -> Gạch POR Ốp_Lát | AH7: =IFERROR(_xlfn.XLOOKUP($C7,'Thông tin về sản phẩm'!$A$2:$A$6228,'Thông tin về sản phẩm'!$AZ$2:$AZ$6228),"") -> 2. Chủ lực
A8: PORCELAIN | B8: 1000x1000 | C8: 10003508 | D8: 41100MARMOL005 | E8: POR 1000x1000, 100MARMOL005, AA | F8: 100MARMOL005 | G8: DOUBLE_CHARGE | H8: 2. Chủ lực | I8: ĐL | J8: 715000 | K8: 572000 | L8: 593000 | O8: 0.2 | P8: 0.17062937 | R8: 543400 | S8: 593000 | T8: 0.24 | U8: =IFERROR(_xlfn.XLOOKUP($C8,'Thông tin về sản phẩm'!$A$2:$A$6228,'Thông tin về sản phẩm'!$F$2:$F$6228),"") -> GẠCH, POR 1000x1000, 100MARMOL005, Loại AA (L1) | V8: =IFERROR(_xlfn.XLOOKUP($C8,'Thông tin về sản phẩm'!$A$2:$A$6228,'Thông tin về sản phẩm'!$S$2:$S$6228),"") -> ỐP_LÁT | W8: =IFERROR(_xlfn.XLOOKUP($C8,'Thông tin về sản phẩm'!$A$2:$A$6228,'Thông tin về sản phẩm'!$Y$2:$Y$6228),"") -> KEM | X8: =IFERROR(_xlfn.XLOOKUP($C8,'Thông tin về sản phẩm'!$A$2:$A$6228,'Thông tin về sản phẩm'!$AA$2:$AA$6228),"") -> ĐẶC_THÙ | Y8: =IFERROR(_xlfn.XLOOKUP($C8,'Thông tin về sản phẩm'!$A$2:$A$6228,'Thông tin về sản phẩm'!$AC$2:$AC$6228),"") -> VÂN_ĐÁ | Z8: =IFERROR(_xlfn.XLOOKUP($C8,'Thông tin về sản phẩm'!$A$2:$A$6228,'Thông tin về sản phẩm'!$AD$2:$AD$6228),"") -> 25.5 | AA8: =IFERROR(_xlfn.XLOOKUP($C8,'Thông tin về sản phẩm'!$A$2:$A$6228,'Thông tin về sản phẩm'!$I$2:$I$6228),"") -> VIE | AB8: =IFERROR(_xlfn.XLOOKUP($C8,'Thông tin về sản phẩm'!$A$2:$A$6228,'Thông tin về sản phẩm'!$AI$2:$AI$6228),"") -> 1000 | AC8: =IFERROR(_xlfn.XLOOKUP($C8,'Thông tin về sản phẩm'!$A$2:$A$6228,'Thông tin về sản phẩm'!$AJ$2:$AJ$6228),"") -> 1000 | AD8: =IFERROR(_xlfn.XLOOKUP($C8,'Thông tin về sản phẩm'!$A$2:$A$6228,'Thông tin về sản phẩm'!$AK$2:$AK$6228),"") -> 11.5 | AE8: =IFERROR(_xlfn.XLOOKUP($C8,'Thông tin về sản phẩm'!$A$2:$A$6228,'Thông tin về sản phẩm'!$AL$2:$AL$6228),"") -> MM | AF8: =IFERROR(_xlfn.XLOOKUP($C8,'Thông tin về sản phẩm'!$A$2:$A$6228,'Thông tin về sản phẩm'!$AM$2:$AM$6228),"") -> MV | AG8: =IFERROR(_xlfn.XLOOKUP($C8,'Thông tin về sản phẩm'!$A$2:$A$6228,'Thông tin về sản phẩm'!$AY$2:$AY$6228),"") -> Gạch POR Ốp_Lát | AH8: =IFERROR(_xlfn.XLOOKUP($C8,'Thông tin về sản phẩm'!$A$2:$A$6228,'Thông tin về sản phẩm'!$AZ$2:$AZ$6228),"") -> 2. Chủ lực
A9: PORCELAIN | B9: 1000x1000 | C9: 10008308 | D9: 41100STONE001-FP-H+ | E9: POR 1000x1000, 100STONE001-FP-H+, AA | F9: 100STONE001-FP-H+ | G9: FP | H9: 1. Chiến lược | I9: ĐL | J9: 562000 | K9: 450000 | L9: 466000 | O9: 0.19928826 | P9: 0.17081851 | R9: 427500 | S9: 466000 | T9: 0.23932384 | U9: =IFERROR(_xlfn.XLOOKUP($C9,'Thông tin về sản phẩm'!$A$2:$A$6228,'Thông tin về sản phẩm'!$F$2:$F$6228),"") -> GẠCH, POR 1000x1000, 100STONE001-FP-H+, Loại AA (L1) | V9: =IFERROR(_xlfn.XLOOKUP($C9,'Thông tin về sản phẩm'!$A$2:$A$6228,'Thông tin về sản phẩm'!$S$2:$S$6228),"") -> ỐP_LÁT | W9: =IFERROR(_xlfn.XLOOKUP($C9,'Thông tin về sản phẩm'!$A$2:$A$6228,'Thông tin về sản phẩm'!$Y$2:$Y$6228),"") -> XÁM | X9: =IFERROR(_xlfn.XLOOKUP($C9,'Thông tin về sản phẩm'!$A$2:$A$6228,'Thông tin về sản phẩm'!$AA$2:$AA$6228),"") -> KHÁNG_KHUẨN | Y9: =IFERROR(_xlfn.XLOOKUP($C9,'Thông tin về sản phẩm'!$A$2:$A$6228,'Thông tin về sản phẩm'!$AC$2:$AC$6228),"") -> VÂN_ĐÁ_MARBLE_CẨM_THẠCH | Z9: =IFERROR(_xlfn.XLOOKUP($C9,'Thông tin về sản phẩm'!$A$2:$A$6228,'Thông tin về sản phẩm'!$AD$2:$AD$6228),"") -> 25.5 | AA9: =IFERROR(_xlfn.XLOOKUP($C9,'Thông tin về sản phẩm'!$A$2:$A$6228,'Thông tin về sản phẩm'!$I$2:$I$6228),"") -> VIE | AB9: =IFERROR(_xlfn.XLOOKUP($C9,'Thông tin về sản phẩm'!$A$2:$A$6228,'Thông tin về sản phẩm'!$AI$2:$AI$6228),"") -> 1000 | AC9: =IFERROR(_xlfn.XLOOKUP($C9,'Thông tin về sản phẩm'!$A$2:$A$6228,'Thông tin về sản phẩm'!$AJ$2:$AJ$6228),"") -> 1000 | AD9: =IFERROR(_xlfn.XLOOKUP($C9,'Thông tin về sản phẩm'!$A$2:$A$6228,'Thông tin về sản phẩm'!$AK$2:$AK$6228),"") -> 11.5 | AE9: =IFERROR(_xlfn.XLOOKUP($C9,'Thông tin về sản phẩm'!$A$2:$A$6228,'Thông tin về sản phẩm'!$AL$2:$AL$6228),"") -> MM | AF9: =IFERROR(_xlfn.XLOOKUP($C9,'Thông tin về sản phẩm'!$A$2:$A$6228,'Thông tin về sản phẩm'!$AM$2:$AM$6228),"") -> MM | AG9: =IFERROR(_xlfn.XLOOKUP($C9,'Thông tin về sản phẩm'!$A$2:$A$6228,'Thông tin về sản phẩm'!$AY$2:$AY$6228),"") -> Gạch POR Ốp_Lát | AH9: =IFERROR(_xlfn.XLOOKUP($C9,'Thông tin về sản phẩm'!$A$2:$A$6228,'Thông tin về sản phẩm'!$AZ$2:$AZ$6228),"") -> 1. Chiến lược
A10: PORCELAIN | B10: 1000x1000 | C10: 10007496 | D10: 41100MOMENT002-H+ | E10: POR 1000x1000, 100MOMENT002-H+, AA | F10: 100MOMENT002-H+ | G10: MỜ | H10: 1. Chiến lược | I10: ĐL | J10: 535000 | K10: 428000 | L10: 444000 | O10: 0.2 | P10: 0.17009346 | R10: 406600 | S10: 444000 | T10: 0.24 | U10: =IFERROR(_xlfn.XLOOKUP($C10,'Thông tin về sản phẩm'!$A$2:$A$6228,'Thông tin về sản phẩm'!$F$2:$F$6228),"") -> GẠCH, POR 1000x1000, 100MOMENT002-H+, Loại AA (L1) | V10: =IFERROR(_xlfn.XLOOKUP($C10,'Thông tin về sản phẩm'!$A$2:$A$6228,'Thông tin về sản phẩm'!$S$2:$S$6228),"") -> ỐP_LÁT | W10: =IFERROR(_xlfn.XLOOKUP($C10,'Thông tin về sản phẩm'!$A$2:$A$6228,'Thông tin về sản phẩm'!$Y$2:$Y$6228),"") -> XÁM | X10: =IFERROR(_xlfn.XLOOKUP($C10,'Thông tin về sản phẩm'!$A$2:$A$6228,'Thông tin về sản phẩm'!$AA$2:$AA$6228),"") -> KHÁNG_KHUẨN | Y10: =IFERROR(_xlfn.XLOOKUP($C10,'Thông tin về sản phẩm'!$A$2:$A$6228,'Thông tin về sản phẩm'!$AC$2:$AC$6228),"") -> VÂN_CÁT | Z10: =IFERROR(_xlfn.XLOOKUP($C10,'Thông tin về sản phẩm'!$A$2:$A$6228,'Thông tin về sản phẩm'!$AD$2:$AD$6228),"") -> 25.5 | AA10: =IFERROR(_xlfn.XLOOKUP($C10,'Thông tin về sản phẩm'!$A$2:$A$6228,'Thông tin về sản phẩm'!$I$2:$I$6228),"") -> VIE | AB10: =IFERROR(_xlfn.XLOOKUP($C10,'Thông tin về sản phẩm'!$A$2:$A$6228,'Thông tin về sản phẩm'!$AI$2:$AI$6228),"") -> 1000 | AC10: =IFERROR(_xlfn.XLOOKUP($C10,'Thông tin về sản phẩm'!$A$2:$A$6228,'Thông tin về sản phẩm'!$AJ$2:$AJ$6228),"") -> 1000 | AD10: =IFERROR(_xlfn.XLOOKUP($C10,'Thông tin về sản phẩm'!$A$2:$A$6228,'Thông tin về sản phẩm'!$AK$2:$AK$6228),"") -> 11.5 | AE10: =IFERROR(_xlfn.XLOOKUP($C10,'Thông tin về sản phẩm'!$A$2:$A$6228,'Thông tin về sản phẩm'!$AL$2:$AL$6228),"") -> MM | AF10: =IFERROR(_xlfn.XLOOKUP($C10,'Thông tin về sản phẩm'!$A$2:$A$6228,'Thông tin về sản phẩm'!$AM$2:$AM$6228),"") -> MM | AG10: =IFERROR(_xlfn.XLOOKUP($C10,'Thông tin về sản phẩm'!$A$2:$A$6228,'Thông tin về sản phẩm'!$AY$2:$AY$6228),"") -> Gạch POR Ốp_Lát | AH10: =IFERROR(_xlfn.XLOOKUP($C10,'Thông tin về sản phẩm'!$A$2:$A$6228,'Thông tin về sản phẩm'!$AZ$2:$AZ$6228),"") -> 1. Chiến lược
A11: PORCELAIN | B11: 1000x1000 | C11: 10007497 | D11: 41100MOMENT003-H+ | E11: POR 1000x1000, 100MOMENT003-H+, AA | F11: 100MOMENT003-H+ | G11: MỜ | H11: 1. Chiến lược | I11: ĐL | J11: 535000 | K11: 428000 | L11: 444000 | O11: 0.2 | P11: 0.17009346 | R11: 406600 | S11: 444000 | T11: 0.24 | U11: =IFERROR(_xlfn.XLOOKUP($C11,'Thông tin về sản phẩm'!$A$2:$A$6228,'Thông tin về sản phẩm'!$F$2:$F$6228),"") -> GẠCH, POR 1000x1000, 100MOMENT003-H+, Loại AA (L1) | V11: =IFERROR(_xlfn.XLOOKUP($C11,'Thông tin về sản phẩm'!$A$2:$A$6228,'Thông tin về sản phẩm'!$S$2:$S$6228),"") -> ỐP_LÁT | W11: =IFERROR(_xlfn.XLOOKUP($C11,'Thông tin về sản phẩm'!$A$2:$A$6228,'Thông tin về sản phẩm'!$Y$2:$Y$6228),"") -> NÂU_XÁM | X11: =IFERROR(_xlfn.XLOOKUP($C11,'Thông tin về sản phẩm'!$A$2:$A$6228,'Thông tin về sản phẩm'!$AA$2:$AA$6228),"") -> KHÁNG_KHUẨN | Y11: =IFERROR(_xlfn.XLOOKUP($C11,'Thông tin về sản phẩm'!$A$2:$A$6228,'Thông tin về sản phẩm'!$AC$2:$AC$6228),"") -> XI_MĂNG | Z11: =IFERROR(_xlfn.XLOOKUP($C11,'Thông tin về sản phẩm'!$A$2:$A$6228,'Thông tin về sản phẩm'!$AD$2:$AD$6228),"") -> 25.5 | AA11: =IFERROR(_xlfn.XLOOKUP($C11,'Thông tin về sản phẩm'!$A$2:$A$6228,'Thông tin về sản phẩm'!$I$2:$I$6228),"") -> VIE | AB11: =IFERROR(_xlfn.XLOOKUP($C11,'Thông tin về sản phẩm'!$A$2:$A$6228,'Thông tin về sản phẩm'!$AI$2:$AI$6228),"") -> 1000 | AC11: =IFERROR(_xlfn.XLOOKUP($C11,'Thông tin về sản phẩm'!$A$2:$A$6228,'Thông tin về sản phẩm'!$AJ$2:$AJ$6228),"") -> 1000 | AD11: =IFERROR(_xlfn.XLOOKUP($C11,'Thông tin về sản phẩm'!$A$2:$A$6228,'Thông tin về sản phẩm'!$AK$2:$AK$6228),"") -> 11.5 | AE11: =IFERROR(_xlfn.XLOOKUP($C11,'Thông tin về sản phẩm'!$A$2:$A$6228,'Thông tin về sản phẩm'!$AL$2:$AL$6228),"") -> MM | AF11: =IFERROR(_xlfn.XLOOKUP($C11,'Thông tin về sản phẩm'!$A$2:$A$6228,'Thông tin về sản phẩm'!$AM$2:$AM$6228),"") -> MM | AG11: =IFERROR(_xlfn.XLOOKUP($C11,'Thông tin về sản phẩm'!$A$2:$A$6228,'Thông tin về sản phẩm'!$AY$2:$AY$6228),"") -> Gạch POR Ốp_Lát | AH11: =IFERROR(_xlfn.XLOOKUP($C11,'Thông tin về sản phẩm'!$A$2:$A$6228,'Thông tin về sản phẩm'!$AZ$2:$AZ$6228),"") -> 1. Chiến lược
A12: PORCELAIN | B12: 1000x1000 | C12: 10007498 | D12: 41100MOMENT004-H+ | E12: POR 1000x1000, 100MOMENT004-H+, AA | F12: 100MOMENT004-H+ | G12: MỜ | H12: 1. Chiến lược | I12: ĐL | J12: 589000 | K12: 471000 | L12: 489000 | O12: 0.20033956 | P12: 0.16977929 | R12: 447450 | S12: 489000 | T12: 0.24032258 | U12: =IFERROR(_xlfn.XLOOKUP($C12,'Thông tin về sản phẩm'!$A$2:$A$6228,'Thông tin về sản phẩm'!$F$2:$F$6228),"") -> GẠCH, POR 1000x1000, 100MOMENT004-H+, Loại AA (L1) | V12: =IFERROR(_xlfn.XLOOKUP($C12,'Thông tin về sản phẩm'!$A$2:$A$6228,'Thông tin về sản phẩm'!$S$2:$S$6228),"") -> ỐP_LÁT | W12: =IFERROR(_xlfn.XLOOKUP($C12,'Thông tin về sản phẩm'!$A$2:$A$6228,'Thông tin về sản phẩm'!$Y$2:$Y$6228),"") -> XÁM | X12: =IFERROR(_xlfn.XLOOKUP($C12,'Thông tin về sản phẩm'!$A$2:$A$6228,'Thông tin về sản phẩm'!$AA$2:$AA$6228),"") -> KHÁNG_KHUẨN | Y12: =IFERROR(_xlfn.XLOOKUP($C12,'Thông tin về sản phẩm'!$A$2:$A$6228,'Thông tin về sản phẩm'!$AC$2:$AC$6228),"") -> XI_MĂNG | Z12: =IFERROR(_xlfn.XLOOKUP($C12,'Thông tin về sản phẩm'!$A$2:$A$6228,'Thông tin về sản phẩm'!$AD$2:$AD$6228),"") -> 25.5 | AA12: =IFERROR(_xlfn.XLOOKUP($C12,'Thông tin về sản phẩm'!$A$2:$A$6228,'Thông tin về sản phẩm'!$I$2:$I$6228),"") -> VIE | AB12: =IFERROR(_xlfn.XLOOKUP($C12,'Thông tin về sản phẩm'!$A$2:$A$6228,'Thông tin về sản phẩm'!$AI$2:$AI$6228),"") -> 1000 | AC12: =IFERROR(_xlfn.XLOOKUP($C12,'Thông tin về sản phẩm'!$A$2:$A$6228,'Thông tin về sản phẩm'!$AJ$2:$AJ$6228),"") -> 1000 | AD12: =IFERROR(_xlfn.XLOOKUP($C12,'Thông tin về sản phẩm'!$A$2:$A$6228,'Thông tin về sản phẩm'!$AK$2:$AK$6228),"") -> 11.5 | AE12: =IFERROR(_xlfn.XLOOKUP($C12,'Thông tin về sản phẩm'!$A$2:$A$6228,'Thông tin về sản phẩm'!$AL$2:$AL$6228),"") -> MM | AF12: =IFERROR(_xlfn.XLOOKUP($C12,'Thông tin về sản phẩm'!$A$2:$A$6228,'Thông tin về sản phẩm'!$AM$2:$AM$6228),"") -> MM | AG12: =IFERROR(_xlfn.XLOOKUP($C12,'Thông tin về sản phẩm'!$A$2:$A$6228,'Thông tin về sản phẩm'!$AY$2:$AY$6228),"") -> Gạch POR Ốp_Lát | AH12: =IFERROR(_xlfn.XLOOKUP($C12,'Thông tin về sản phẩm'!$A$2:$A$6228,'Thông tin về sản phẩm'!$AZ$2:$AZ$6228),"") -> 1. Chiến lược
A13: PORCELAIN | B13: 1000x1000 | C13: 10007499 | D13: 41100MOMENT001-H+ | E13: POR 1000x1000, 100MOMENT001-H+, AA | F13: 100MOMENT001-H+ | G13: MỜ | H13: 1. Chiến lược | I13: ĐL | J13: 535000 | K13: 428000 | L13: 444000 | O13: 0.2 | P13: 0.17009346 | R13: 406600 | S13: 444000 | T13: 0.24 | U13: =IFERROR(_xlfn.XLOOKUP($C13,'Thông tin về sản phẩm'!$A$2:$A$6228,'Thông tin về sản phẩm'!$F$2:$F$6228),"") -> GẠCH, POR 1000x1000, 100MOMENT001-H+, Loại AA (L1) | V13: =IFERROR(_xlfn.XLOOKUP($C13,'Thông tin về sản phẩm'!$A$2:$A$6228,'Thông tin về sản phẩm'!$S$2:$S$6228),"") -> ỐP_LÁT | W13: =IFERROR(_xlfn.XLOOKUP($C13,'Thông tin về sản phẩm'!$A$2:$A$6228,'Thông tin về sản phẩm'!$Y$2:$Y$6228),"") -> TRẮNG | X13: =IFERROR(_xlfn.XLOOKUP($C13,'Thông tin về sản phẩm'!$A$2:$A$6228,'Thông tin về sản phẩm'!$AA$2:$AA$6228),"") -> KHÁNG_KHUẨN | Y13: =IFERROR(_xlfn.XLOOKUP($C13,'Thông tin về sản phẩm'!$A$2:$A$6228,'Thông tin về sản phẩm'!$AC$2:$AC$6228),"") -> VÂN_ĐÁ_MARBLE_CẨM_THẠCH | Z13: =IFERROR(_xlfn.XLOOKUP($C13,'Thông tin về sản phẩm'!$A$2:$A$6228,'Thông tin về sản phẩm'!$AD$2:$AD$6228),"") -> 25.5 | AA13: =IFERROR(_xlfn.XLOOKUP($C13,'Thông tin về sản phẩm'!$A$2:$A$6228,'Thông tin về sản phẩm'!$I$2:$I$6228),"") -> VIE | AB13: =IFERROR(_xlfn.XLOOKUP($C13,'Thông tin về sản phẩm'!$A$2:$A$6228,'Thông tin về sản phẩm'!$AI$2:$AI$6228),"") -> 1000 | AC13: =IFERROR(_xlfn.XLOOKUP($C13,'Thông tin về sản phẩm'!$A$2:$A$6228,'Thông tin về sản phẩm'!$AJ$2:$AJ$6228),"") -> 1000 | AD13: =IFERROR(_xlfn.XLOOKUP($C13,'Thông tin về sản phẩm'!$A$2:$A$6228,'Thông tin về sản phẩm'!$AK$2:$AK$6228),"") -> 11.5 | AE13: =IFERROR(_xlfn.XLOOKUP($C13,'Thông tin về sản phẩm'!$A$2:$A$6228,'Thông tin về sản phẩm'!$AL$2:$AL$6228),"") -> MM | AF13: =IFERROR(_xlfn.XLOOKUP($C13,'Thông tin về sản phẩm'!$A$2:$A$6228,'Thông tin về sản phẩm'!$AM$2:$AM$6228),"") -> MM | AG13: =IFERROR(_xlfn.XLOOKUP($C13,'Thông tin về sản phẩm'!$A$2:$A$6228,'Thông tin về sản phẩm'!$AY$2:$AY$6228),"") -> Gạch POR Ốp_Lát | AH13: =IFERROR(_xlfn.XLOOKUP($C13,'Thông tin về sản phẩm'!$A$2:$A$6228,'Thông tin về sản phẩm'!$AZ$2:$AZ$6228),"") -> 1. Chiến lược
A14: PORCELAIN | B14: 1000x1000 | C14: 10007500 | D14: 41100CARARAS002-FP-H+ | E14: POR 1000x1000, 100CARARAS002-FP-H+, AA | F14: 100CARARAS002-FP-H+ | G14: FP | H14: 1. Chiến lược | I14: ĐL | J14: 562000 | K14: 450000 | L14: 466000 | O14: 0.19928826 | P14: 0.17081851 | R14: 427500 | S14: 466000 | T14: 0.23932384 | U14: =IFERROR(_xlfn.XLOOKUP($C14,'Thông tin về sản phẩm'!$A$2:$A$6228,'Thông tin về sản phẩm'!$F$2:$F$6228),"") -> GẠCH, POR 1000x1000, 100CARARAS002-FP-H+, Loại AA (L1) | V14: =IFERROR(_xlfn.XLOOKUP($C14,'Thông tin về sản phẩm'!$A$2:$A$6228,'Thông tin về sản phẩm'!$S$2:$S$6228),"") -> ỐP_LÁT | W14: =IFERROR(_xlfn.XLOOKUP($C14,'Thông tin về sản phẩm'!$A$2:$A$6228,'Thông tin về sản phẩm'!$Y$2:$Y$6228),"") -> TRẮNG | X14: =IFERROR(_xlfn.XLOOKUP($C14,'Thông tin về sản phẩm'!$A$2:$A$6228,'Thông tin về sản phẩm'!$AA$2:$AA$6228),"") -> KHÁNG_KHUẨN | Y14: =IFERROR(_xlfn.XLOOKUP($C14,'Thông tin về sản phẩm'!$A$2:$A$6228,'Thông tin về sản phẩm'!$AC$2:$AC$6228),"") -> VÂN_ĐÁ_CARARAS | Z14: =IFERROR(_xlfn.XLOOKUP($C14,'Thông tin về sản phẩm'!$A$2:$A$6228,'Thông tin về sản phẩm'!$AD$2:$AD$6228),"") -> 25.5 | AA14: =IFERROR(_xlfn.XLOOKUP($C14,'Thông tin về sản phẩm'!$A$2:$A$6228,'Thông tin về sản phẩm'!$I$2:$I$6228),"") -> VIE | AB14: =IFERROR(_xlfn.XLOOKUP($C14,'Thông tin về sản phẩm'!$A$2:$A$6228,'Thông tin về sản phẩm'!$AI$2:$AI$6228),"") -> 1000 | AC14: =IFERROR(_xlfn.XLOOKUP($C14,'Thông tin về sản phẩm'!$A$2:$A$6228,'Thông tin về sản phẩm'!$AJ$2:$AJ$6228),"") -> 1000 | AD14: =IFERROR(_xlfn.XLOOKUP($C14,'Thông tin về sản phẩm'!$A$2:$A$6228,'Thông tin về sản phẩm'!$AK$2:$AK$6228),"") -> 11.5 | AE14: =IFERROR(_xlfn.XLOOKUP($C14,'Thông tin về sản phẩm'!$A$2:$A$6228,'Thông tin về sản phẩm'!$AL$2:$AL$6228),"") -> MM | AF14: =IFERROR(_xlfn.XLOOKUP($C14,'Thông tin về sản phẩm'!$A$2:$A$6228,'Thông tin về sản phẩm'!$AM$2:$AM$6228),"") -> MM | AG14: =IFERROR(_xlfn.XLOOKUP($C14,'Thông tin về sản phẩm'!$A$2:$A$6228,'Thông tin về sản phẩm'!$AY$2:$AY$6228),"") -> Gạch POR Ốp_Lát | AH14: =IFERROR(_xlfn.XLOOKUP($C14,'Thông tin về sản phẩm'!$A$2:$A$6228,'Thông tin về sản phẩm'!$AZ$2:$AZ$6228),"") -> 1. Chiến lược
... A16: PORCELAIN | B16: 1000x1000 | C16: 10007495 | D16: 41100BARI001-H+ | E16: POR 1000x1000, 100BARI001-H+, AA | F16: 100BARI001-H+ | G16: MỜ | H16: 1. Chiến lược | I16: ĐL | J16: 589000 | K16: 471000 | L16: 489000 | O16: 0.20033956 | P16: 0.16977929 | R16: 447450 | S16: 489000 | T16: 0.24032258 | U16: =IFERROR(_xlfn.XLOOKUP($C16,'Thông tin về sản phẩm'!$A$2:$A$6228,'Thông tin về sản phẩm'!$F$2:$F$6228),"") -> GẠCH, POR 1000x1000, 100BARI001-H+, Loại AA (L1) | V16: =IFERROR(_xlfn.XLOOKUP($C16,'Thông tin về sản phẩm'!$A$2:$A$6228,'Thông tin về sản phẩm'!$S$2:$S$6228),"") -> ỐP_LÁT | W16: =IFERROR(_xlfn.XLOOKUP($C16,'Thông tin về sản phẩm'!$A$2:$A$6228,'Thông tin về sản phẩm'!$Y$2:$Y$6228),"") -> TRẮNG | X16: =IFERROR(_xlfn.XLOOKUP($C16,'Thông tin về sản phẩm'!$A$2:$A$6228,'Thông tin về sản phẩm'!$AA$2:$AA$6228),"") -> KHÁNG_KHUẨN | Y16: =IFERROR(_xlfn.XLOOKUP($C16,'Thông tin về sản phẩm'!$A$2:$A$6228,'Thông tin về sản phẩm'!$AC$2:$AC$6228),"") -> VÂN_CÁT | Z16: =IFERROR(_xlfn.XLOOKUP($C16,'Thông tin về sản phẩm'!$A$2:$A$6228,'Thông tin về sản phẩm'!$AD$2:$AD$6228),"") -> 25.5 | AA16: =IFERROR(_xlfn.XLOOKUP($C16,'Thông tin về sản phẩm'!$A$2:$A$6228,'Thông tin về sản phẩm'!$I$2:$I$6228),"") -> VIE | AB16: =IFERROR(_xlfn.XLOOKUP($C16,'Thông tin về sản phẩm'!$A$2:$A$6228,'Thông tin về sản phẩm'!$AI$2:$AI$6228),"") -> 1000 | AC16: =IFERROR(_xlfn.XLOOKUP($C16,'Thông tin về sản phẩm'!$A$2:$A$6228,'Thông tin về sản phẩm'!$AJ$2:$AJ$6228),"") -> 1000 | AD16: =IFERROR(_xlfn.XLOOKUP($C16,'Thông tin về sản phẩm'!$A$2:$A$6228,'Thông tin về sản phẩm'!$AK$2:$AK$6228),"") -> 11.5 | AE16: =IFERROR(_xlfn.XLOOKUP($C16,'Thông tin về sản phẩm'!$A$2:$A$6228,'Thông tin về sản phẩm'!$AL$2:$AL$6228),"") -> MM | AF16: =IFERROR(_xlfn.XLOOKUP($C16,'Thông tin về sản phẩm'!$A$2:$A$6228,'Thông tin về sản phẩm'!$AM$2:$AM$6228),"") -> MM | AG16: =IFERROR(_xlfn.XLOOKUP($C16,'Thông tin về sản phẩm'!$A$2:$A$6228,'Thông tin về sản phẩm'!$AY$2:$AY$6228),"") -> Gạch POR Ốp_Lát | AH16: =IFERROR(_xlfn.XLOOKUP($C16,'Thông tin về sản phẩm'!$A$2:$A$6228,'Thông tin về sản phẩm'!$AZ$2:$AZ$6228),"") -> 1. Chiến lược
A17: PORCELAIN | B17: 1000x1000 | C17: 10005899 | D17: 41100DONGVAN007-FP-H+ | E17: POR 1000x1000, 100DONGVAN007-FP-H+, AA | F17: 100DONGVAN007-FP-H+ | G17: FP | I17: Sale | J17: 562000 | K17: 449600 | L17: 466460 | M17: 382200 | N17: 399000 | O17: 0.2 | P17: 0.17 | Q17: 📦 Xả kho (CT2 – TB 173) | R17: 363090 | S17: 399000 | T17: 0.35393238 | U17: =IFERROR(_xlfn.XLOOKUP($C17,'Thông tin về sản phẩm'!$A$2:$A$6228,'Thông tin về sản phẩm'!$F$2:$F$6228),"") -> GẠCH, POR 1000x1000, 100DONGVAN007-FP-H+, Loại AA (L1) | V17: =IFERROR(_xlfn.XLOOKUP($C17,'Thông tin về sản phẩm'!$A$2:$A$6228,'Thông tin về sản phẩm'!$S$2:$S$6228),"") -> ỐP_LÁT | W17: =IFERROR(_xlfn.XLOOKUP($C17,'Thông tin về sản phẩm'!$A$2:$A$6228,'Thông tin về sản phẩm'!$Y$2:$Y$6228),"") -> XÁM | X17: =IFERROR(_xlfn.XLOOKUP($C17,'Thông tin về sản phẩm'!$A$2:$A$6228,'Thông tin về sản phẩm'!$AA$2:$AA$6228),"") -> KHÁNG_KHUẨN | Y17: =IFERROR(_xlfn.XLOOKUP($C17,'Thông tin về sản phẩm'!$A$2:$A$6228,'Thông tin về sản phẩm'!$AC$2:$AC$6228),"") -> VÂN_ĐÁ_MARBLE_CẨM_THẠCH | Z17: =IFERROR(_xlfn.XLOOKUP($C17,'Thông tin về sản phẩm'!$A$2:$A$6228,'Thông tin về sản phẩm'!$AD$2:$AD$6228),"") -> 28.55 | AA17: =IFERROR(_xlfn.XLOOKUP($C17,'Thông tin về sản phẩm'!$A$2:$A$6228,'Thông tin về sản phẩm'!$I$2:$I$6228),"") -> VIE | AB17: =IFERROR(_xlfn.XLOOKUP($C17,'Thông tin về sản phẩm'!$A$2:$A$6228,'Thông tin về sản phẩm'!$AI$2:$AI$6228),"") -> 1000 | AC17: =IFERROR(_xlfn.XLOOKUP($C17,'Thông tin về sản phẩm'!$A$2:$A$6228,'Thông tin về sản phẩm'!$AJ$2:$AJ$6228),"") -> 1000 | AD17: =IFERROR(_xlfn.XLOOKUP($C17,'Thông tin về sản phẩm'!$A$2:$A$6228,'Thông tin về sản phẩm'!$AK$2:$AK$6228),"") -> 11.5 | AE17: =IFERROR(_xlfn.XLOOKUP($C17,'Thông tin về sản phẩm'!$A$2:$A$6228,'Thông tin về sản phẩm'!$AL$2:$AL$6228),"") -> MM | AF17: =IFERROR(_xlfn.XLOOKUP($C17,'Thông tin về sản phẩm'!$A$2:$A$6228,'Thông tin về sản phẩm'!$AM$2:$AM$6228),"") -> BM | AG17: =IFERROR(_xlfn.XLOOKUP($C17,'Thông tin về sản phẩm'!$A$2:$A$6228,'Thông tin về sản phẩm'!$AY$2:$AY$6228),"") -> Gạch POR Ốp_Lát | AH17: =IFERROR(_xlfn.XLOOKUP($C17,'Thông tin về sản phẩm'!$A$2:$A$6228,'Thông tin về sản phẩm'!$AZ$2:$AZ$6228),"") -> 5. Cơ bản
A18: PORCELAIN | B18: 1000x1000 | C18: 10005900 | D18: 41100DONGVAN005-FP-H+ | E18: POR 1000x1000, 100DONGVAN005-FP-H+, AA | F18: 100DONGVAN005-FP-H+ | G18: FP | I18: Sale | J18: 618000 | K18: 494400 | L18: 512940 | M18: 420200 | N18: 438800 | O18: 0.2 | P18: 0.17 | Q18: 🔥 Sale tháng (CT1 – TB 169) | R18: 399190 | S18: 438800 | T18: 0.35406149 | U18: =IFERROR(_xlfn.XLOOKUP($C18,'Thông tin về sản phẩm'!$A$2:$A$6228,'Thông tin về sản phẩm'!$F$2:$F$6228),"") -> GẠCH, POR 1000x1000, 100DONGVAN005-FP-H+, Loại AA (L1) | V18: =IFERROR(_xlfn.XLOOKUP($C18,'Thông tin về sản phẩm'!$A$2:$A$6228,'Thông tin về sản phẩm'!$S$2:$S$6228),"") -> ỐP_LÁT | W18: =IFERROR(_xlfn.XLOOKUP($C18,'Thông tin về sản phẩm'!$A$2:$A$6228,'Thông tin về sản phẩm'!$Y$2:$Y$6228),"") -> XÁM | X18: =IFERROR(_xlfn.XLOOKUP($C18,'Thông tin về sản phẩm'!$A$2:$A$6228,'Thông tin về sản phẩm'!$AA$2:$AA$6228),"") -> KHÁNG_KHUẨN | Y18: =IFERROR(_xlfn.XLOOKUP($C18,'Thông tin về sản phẩm'!$A$2:$A$6228,'Thông tin về sản phẩm'!$AC$2:$AC$6228),"") -> VÂN_ĐÁ_MARBLE_CẨM_THẠCH | Z18: =IFERROR(_xlfn.XLOOKUP($C18,'Thông tin về sản phẩm'!$A$2:$A$6228,'Thông tin về sản phẩm'!$AD$2:$AD$6228),"") -> 28.55 | AA18: =IFERROR(_xlfn.XLOOKUP($C18,'Thông tin về sản phẩm'!$A$2:$A$6228,'Thông tin về sản phẩm'!$I$2:$I$6228),"") -> VIE | AB18: =IFERROR(_xlfn.XLOOKUP($C18,'Thông tin về sản phẩm'!$A$2:$A$6228,'Thông tin về sản phẩm'!$AI$2:$AI$6228),"") -> 1000 | AC18: =IFERROR(_xlfn.XLOOKUP($C18,'Thông tin về sản phẩm'!$A$2:$A$6228,'Thông tin về sản phẩm'!$AJ$2:$AJ$6228),"") -> 1000 | AD18: =IFERROR(_xlfn.XLOOKUP($C18,'Thông tin về sản phẩm'!$A$2:$A$6228,'Thông tin về sản phẩm'!$AK$2:$AK$6228),"") -> 11.5 | AE18: =IFERROR(_xlfn.XLOOKUP($C18,'Thông tin về sản phẩm'!$A$2:$A$6228,'Thông tin về sản phẩm'!$AL$2:$AL$6228),"") -> MM | AF18: =IFERROR(_xlfn.XLOOKUP($C18,'Thông tin về sản phẩm'!$A$2:$A$6228,'Thông tin về sản phẩm'!$AM$2:$AM$6228),"") -> MD | AG18: =IFERROR(_xlfn.XLOOKUP($C18,'Thông tin về sản phẩm'!$A$2:$A$6228,'Thông tin về sản phẩm'!$AY$2:$AY$6228),"") -> Gạch POR Ốp_Lát | AH18: =IFERROR(_xlfn.XLOOKUP($C18,'Thông tin về sản phẩm'!$A$2:$A$6228,'Thông tin về sản phẩm'!$AZ$2:$AZ$6228),"") -> 4. Tiềm năng
A19: PORCELAIN | B19: 1000x1000 | C19: 10001052 | D19: 41100VICTORIA005 | E19: POR 1000x1000, 100VICTORIA005, AA | F19: 100VICTORIA005 | G19: ĐỒNG_CHẤT | I19: Sale | J19: 713000 | K19: 570400 | L19: 591790 | M19: 484800 | N19: 506200 | O19: 0.2 | P19: 0.17 | Q19: 🔥 Sale tháng (CT1 – TB 169) | R19: 460560 | S19: 506200 | T19: 0.3540533 | U19: =IFERROR(_xlfn.XLOOKUP($C19,'Thông tin về sản phẩm'!$A$2:$A$6228,'Thông tin về sản phẩm'!$F$2:$F$6228),"") -> GẠCH, POR 1000x1000, 100VICTORIA005, Loại AA (L1) | V19: =IFERROR(_xlfn.XLOOKUP($C19,'Thông tin về sản phẩm'!$A$2:$A$6228,'Thông tin về sản phẩm'!$S$2:$S$6228),"") -> ỐP_LÁT | W19: =IFERROR(_xlfn.XLOOKUP($C19,'Thông tin về sản phẩm'!$A$2:$A$6228,'Thông tin về sản phẩm'!$Y$2:$Y$6228),"") -> TRẮNG | X19: =IFERROR(_xlfn.XLOOKUP($C19,'Thông tin về sản phẩm'!$A$2:$A$6228,'Thông tin về sản phẩm'!$AA$2:$AA$6228),"") -> ĐẶC_THÙ | Y19: =IFERROR(_xlfn.XLOOKUP($C19,'Thông tin về sản phẩm'!$A$2:$A$6228,'Thông tin về sản phẩm'!$AC$2:$AC$6228),"") -> MUỐI_TIÊU | Z19: =IFERROR(_xlfn.XLOOKUP($C19,'Thông tin về sản phẩm'!$A$2:$A$6228,'Thông tin về sản phẩm'!$AD$2:$AD$6228),"") -> 28.55 | AA19: =IFERROR(_xlfn.XLOOKUP($C19,'Thông tin về sản phẩm'!$A$2:$A$6228,'Thông tin về sản phẩm'!$I$2:$I$6228),"") -> VIE | AB19: =IFERROR(_xlfn.XLOOKUP($C19,'Thông tin về sản phẩm'!$A$2:$A$6228,'Thông tin về sản phẩm'!$AI$2:$AI$6228),"") -> 1000 | AC19: =IFERROR(_xlfn.XLOOKUP($C19,'Thông tin về sản phẩm'!$A$2:$A$6228,'Thông tin về sản phẩm'!$AJ$2:$AJ$6228),"") -> 1000 | AD19: =IFERROR(_xlfn.XLOOKUP($C19,'Thông tin về sản phẩm'!$A$2:$A$6228,'Thông tin về sản phẩm'!$AK$2:$AK$6228),"") -> 11.5 | AE19: =IFERROR(_xlfn.XLOOKUP($C19,'Thông tin về sản phẩm'!$A$2:$A$6228,'Thông tin về sản phẩm'!$AL$2:$AL$6228),"") -> MM | AF19: =IFERROR(_xlfn.XLOOKUP($C19,'Thông tin về sản phẩm'!$A$2:$A$6228,'Thông tin về sản phẩm'!$AM$2:$AM$6228),"") -> MV | AG19: =IFERROR(_xlfn.XLOOKUP($C19,'Thông tin về sản phẩm'!$A$2:$A$6228,'Thông tin về sản phẩm'!$AY$2:$AY$6228),"") -> Gạch POR Ốp_Lát | AH19: =IFERROR(_xlfn.XLOOKUP($C19,'Thông tin về sản phẩm'!$A$2:$A$6228,'Thông tin về sản phẩm'!$AZ$2:$AZ$6228),"") -> 4. Tiềm năng
A20: PORCELAIN | B20: 1000x1000 | C20: 10005895 | D20: 41100DONGVAN004-FP-H+ | E20: POR 1000x1000, 100DONGVAN004-FP-H+, AA | F20: 100DONGVAN004-FP-H+ | G20: FP | I20: Sale | J20: 618000 | K20: 494400 | L20: 512940 | M20: 420200 | N20: 438800 | O20: 0.2 | P20: 0.17 | Q20: 🔥 Sale tháng (CT1 – TB 169) | R20: 399190 | S20: 438800 | T20: 0.35406149 | U20: =IFERROR(_xlfn.XLOOKUP($C20,'Thông tin về sản phẩm'!$A$2:$A$6228,'Thông tin về sản phẩm'!$F$2:$F$6228),"") -> GẠCH, POR 1000x1000, 100DONGVAN004-FP-H+, Loại AA (L1) | V20: =IFERROR(_xlfn.XLOOKUP($C20,'Thông tin về sản phẩm'!$A$2:$A$6228,'Thông tin về sản phẩm'!$S$2:$S$6228),"") -> ỐP_LÁT | W20: =IFERROR(_xlfn.XLOOKUP($C20,'Thông tin về sản phẩm'!$A$2:$A$6228,'Thông tin về sản phẩm'!$Y$2:$Y$6228),"") -> TRẮNG | X20: =IFERROR(_xlfn.XLOOKUP($C20,'Thông tin về sản phẩm'!$A$2:$A$6228,'Thông tin về sản phẩm'!$AA$2:$AA$6228),"") -> KHÁNG_KHUẨN | Y20: =IFERROR(_xlfn.XLOOKUP($C20,'Thông tin về sản phẩm'!$A$2:$A$6228,'Thông tin về sản phẩm'!$AC$2:$AC$6228),"") -> VÂN_ĐÁ_CARARAS | Z20: =IFERROR(_xlfn.XLOOKUP($C20,'Thông tin về sản phẩm'!$A$2:$A$6228,'Thông tin về sản phẩm'!$AD$2:$AD$6228),"") -> 28.55 | AA20: =IFERROR(_xlfn.XLOOKUP($C20,'Thông tin về sản phẩm'!$A$2:$A$6228,'Thông tin về sản phẩm'!$I$2:$I$6228),"") -> VIE | AB20: =IFERROR(_xlfn.XLOOKUP($C20,'Thông tin về sản phẩm'!$A$2:$A$6228,'Thông tin về sản phẩm'!$AI$2:$AI$6228),"") -> 1000 | AC20: =IFERROR(_xlfn.XLOOKUP($C20,'Thông tin về sản phẩm'!$A$2:$A$6228,'Thông tin về sản phẩm'!$AJ$2:$AJ$6228),"") -> 1000 | AD20: =IFERROR(_xlfn.XLOOKUP($C20,'Thông tin về sản phẩm'!$A$2:$A$6228,'Thông tin về sản phẩm'!$AK$2:$AK$6228),"") -> 11.5 | AE20: =IFERROR(_xlfn.XLOOKUP($C20,'Thông tin về sản phẩm'!$A$2:$A$6228,'Thông tin về sản phẩm'!$AL$2:$AL$6228),"") -> MM | AF20: =IFERROR(_xlfn.XLOOKUP($C20,'Thông tin về sản phẩm'!$A$2:$A$6228,'Thông tin về sản phẩm'!$AM$2:$AM$6228),"") -> MD | AG20: =IFERROR(_xlfn.XLOOKUP($C20,'Thông tin về sản phẩm'!$A$2:$A$6228,'Thông tin về sản phẩm'!$AY$2:$AY$6228),"") -> Gạch POR Ốp_Lát | AH20: =IFERROR(_xlfn.XLOOKUP($C20,'Thông tin về sản phẩm'!$A$2:$A$6228,'Thông tin về sản phẩm'!$AZ$2:$AZ$6228),"") -> 4. Tiềm năng
A21: PORCELAIN | B21: 1000x1000 | C21: 10006646 | D21: 41100BABYLON002-H+ | E21: POR 1000x1000, 100BABYLON002-H+, AA | F21: 100BABYLON002 | G21: MỜ | U21: =IFERROR(_xlfn.XLOOKUP($C21,'Thông tin về sản phẩm'!$A$2:$A$6228,'Thông tin về sản phẩm'!$F$2:$F$6228),"") -> GẠCH, POR 1000x1000, 100BABYLON002-H+, Loại AA (L1) | V21: =IFERROR(_xlfn.XLOOKUP($C21,'Thông tin về sản phẩm'!$A$2:$A$6228,'Thông tin về sản phẩm'!$S$2:$S$6228),"") -> ỐP_LÁT | W21: =IFERROR(_xlfn.XLOOKUP($C21,'Thông tin về sản phẩm'!$A$2:$A$6228,'Thông tin về sản phẩm'!$Y$2:$Y$6228),"") -> KEM | X21: =IFERROR(_xlfn.XLOOKUP($C21,'Thông tin về sản phẩm'!$A$2:$A$6228,'Thông tin về sản phẩm'!$AA$2:$AA$6228),"") -> KHÁNG_KHUẨN | Y21: =IFERROR(_xlfn.XLOOKUP($C21,'Thông tin về sản phẩm'!$A$2:$A$6228,'Thông tin về sản phẩm'!$AC$2:$AC$6228),"") -> VÂN_ĐÁ | Z21: =IFERROR(_xlfn.XLOOKUP($C21,'Thông tin về sản phẩm'!$A$2:$A$6228,'Thông tin về sản phẩm'!$AD$2:$AD$6228),"") -> 28.55 | AA21: =IFERROR(_xlfn.XLOOKUP($C21,'Thông tin về sản phẩm'!$A$2:$A$6228,'Thông tin về sản phẩm'!$I$2:$I$6228),"") -> VIE | AB21: =IFERROR(_xlfn.XLOOKUP($C21,'Thông tin về sản phẩm'!$A$2:$A$6228,'Thông tin về sản phẩm'!$AI$2:$AI$6228),"") -> 1000 | AC21: =IFERROR(_xlfn.XLOOKUP($C21,'Thông tin về sản phẩm'!$A$2:$A$6228,'Thông tin về sản phẩm'!$AJ$2:$AJ$6228),"") -> 1000 | AD21: =IFERROR(_xlfn.XLOOKUP($C21,'Thông tin về sản phẩm'!$A$2:$A$6228,'Thông tin về sản phẩm'!$AK$2:$AK$6228),"") -> 11.5 | AE21: =IFERROR(_xlfn.XLOOKUP($C21,'Thông tin về sản phẩm'!$A$2:$A$6228,'Thông tin về sản phẩm'!$AL$2:$AL$6228),"") -> MM | AF21: =IFERROR(_xlfn.XLOOKUP($C21,'Thông tin về sản phẩm'!$A$2:$A$6228,'Thông tin về sản phẩm'!$AM$2:$AM$6228),"") -> MM | AG21: =IFERROR(_xlfn.XLOOKUP($C21,'Thông tin về sản phẩm'!$A$2:$A$6228,'Thông tin về sản phẩm'!$AY$2:$AY$6228),"") -> Gạch POR Ốp_Lát | AH21: =IFERROR(_xlfn.XLOOKUP($C21,'Thông tin về sản phẩm'!$A$2:$A$6228,'Thông tin về sản phẩm'!$AZ$2:$AZ$6228),"")
A22: PORCELAIN | B22: 1000x1000 | C22: 10006772 | D22: 41100BABYLON003-H+ | E22: POR 1000x1000, 100BABYLON003-H+, AA | F22: 100BABYLON003 | G22: MỜ | U22: =IFERROR(_xlfn.XLOOKUP($C22,'Thông tin về sản phẩm'!$A$2:$A$6228,'Thông tin về sản phẩm'!$F$2:$F$6228),"") -> GẠCH, POR 1000x1000, 100BABYLON003-H+, Loại AA (L1) | V22: =IFERROR(_xlfn.XLOOKUP($C22,'Thông tin về sản phẩm'!$A$2:$A$6228,'Thông tin về sản phẩm'!$S$2:$S$6228),"") -> ỐP_LÁT | W22: =IFERROR(_xlfn.XLOOKUP($C22,'Thông tin về sản phẩm'!$A$2:$A$6228,'Thông tin về sản phẩm'!$Y$2:$Y$6228),"") -> KEM | X22: =IFERROR(_xlfn.XLOOKUP($C22,'Thông tin về sản phẩm'!$A$2:$A$6228,'Thông tin về sản phẩm'!$AA$2:$AA$6228),"") -> KHÁNG_KHUẨN | Y22: =IFERROR(_xlfn.XLOOKUP($C22,'Thông tin về sản phẩm'!$A$2:$A$6228,'Thông tin về sản phẩm'!$AC$2:$AC$6228),"") -> VÂN_ĐÁ_MARBLE_CẨM_THẠCH | Z22: =IFERROR(_xlfn.XLOOKUP($C22,'Thông tin về sản phẩm'!$A$2:$A$6228,'Thông tin về sản phẩm'!$AD$2:$AD$6228),"") -> 28.55 | AA22: =IFERROR(_xlfn.XLOOKUP($C22,'Thông tin về sản phẩm'!$A$2:$A$6228,'Thông tin về sản phẩm'!$I$2:$I$6228),"") -> VIE | AB22: =IFERROR(_xlfn.XLOOKUP($C22,'Thông tin về sản phẩm'!$A$2:$A$6228,'Thông tin về sản phẩm'!$AI$2:$AI$6228),"") -> 1000 | AC22: =IFERROR(_xlfn.XLOOKUP($C22,'Thông tin về sản phẩm'!$A$2:$A$6228,'Thông tin về sản phẩm'!$AJ$2:$AJ$6228),"") -> 1000 | AD22: =IFERROR(_xlfn.XLOOKUP($C22,'Thông tin về sản phẩm'!$A$2:$A$6228,'Thông tin về sản phẩm'!$AK$2:$AK$6228),"") -> 11.5 | AE22: =IFERROR(_xlfn.XLOOKUP($C22,'Thông tin về sản phẩm'!$A$2:$A$6228,'Thông tin về sản phẩm'!$AL$2:$AL$6228),"") -> MM | AF22: =IFERROR(_xlfn.XLOOKUP($C22,'Thông tin về sản phẩm'!$A$2:$A$6228,'Thông tin về sản phẩm'!$AM$2:$AM$6228),"") -> MM | AG22: =IFERROR(_xlfn.XLOOKUP($C22,'Thông tin về sản phẩm'!$A$2:$A$6228,'Thông tin về sản phẩm'!$AY$2:$AY$6228),"") -> Gạch POR Ốp_Lát | AH22: =IFERROR(_xlfn.XLOOKUP($C22,'Thông tin về sản phẩm'!$A$2:$A$6228,'Thông tin về sản phẩm'!$AZ$2:$AZ$6228),"")
A23: PORCELAIN | B23: 1000x1000 | C23: 10006774 | D23: 41100BABYLON005-H+ | E23: POR 1000x1000, 100BABYLON005-H+, AA | F23: 100BABYLON005-H+ | G23: MỜ | U23: =IFERROR(_xlfn.XLOOKUP($C23,'Thông tin về sản phẩm'!$A$2:$A$6228,'Thông tin về sản phẩm'!$F$2:$F$6228),"") -> GẠCH, POR 1000x1000, 100BABYLON005-H+, Loại AA (L1) | V23: =IFERROR(_xlfn.XLOOKUP($C23,'Thông tin về sản phẩm'!$A$2:$A$6228,'Thông tin về sản phẩm'!$S$2:$S$6228),"") -> ỐP_LÁT | W23: =IFERROR(_xlfn.XLOOKUP($C23,'Thông tin về sản phẩm'!$A$2:$A$6228,'Thông tin về sản phẩm'!$Y$2:$Y$6228),"") -> XÁM | X23: =IFERROR(_xlfn.XLOOKUP($C23,'Thông tin về sản phẩm'!$A$2:$A$6228,'Thông tin về sản phẩm'!$AA$2:$AA$6228),"") -> KHÁNG_KHUẨN | Y23: =IFERROR(_xlfn.XLOOKUP($C23,'Thông tin về sản phẩm'!$A$2:$A$6228,'Thông tin về sản phẩm'!$AC$2:$AC$6228),"") -> VÂN_ĐÁ_CREMA_MAFIL | Z23: =IFERROR(_xlfn.XLOOKUP($C23,'Thông tin về sản phẩm'!$A$2:$A$6228,'Thông tin về sản phẩm'!$AD$2:$AD$6228),"") -> 28.55 | AA23: =IFERROR(_xlfn.XLOOKUP($C23,'Thông tin về sản phẩm'!$A$2:$A$6228,'Thông tin về sản phẩm'!$I$2:$I$6228),"") -> VIE | AB23: =IFERROR(_xlfn.XLOOKUP($C23,'Thông tin về sản phẩm'!$A$2:$A$6228,'Thông tin về sản phẩm'!$AI$2:$AI$6228),"") -> 1000 | AC23: =IFERROR(_xlfn.XLOOKUP($C23,'Thông tin về sản phẩm'!$A$2:$A$6228,'Thông tin về sản phẩm'!$AJ$2:$AJ$6228),"") -> 1000 | AD23: =IFERROR(_xlfn.XLOOKUP($C23,'Thông tin về sản phẩm'!$A$2:$A$6228,'Thông tin về sản phẩm'!$AK$2:$AK$6228),"") -> 11.5 | AE23: =IFERROR(_xlfn.XLOOKUP($C23,'Thông tin về sản phẩm'!$A$2:$A$6228,'Thông tin về sản phẩm'!$AL$2:$AL$6228),"") -> MM | AF23: =IFERROR(_xlfn.XLOOKUP($C23,'Thông tin về sản phẩm'!$A$2:$A$6228,'Thông tin về sản phẩm'!$AM$2:$AM$6228),"") -> MM | AG23: =IFERROR(_xlfn.XLOOKUP($C23,'Thông tin về sản phẩm'!$A$2:$A$6228,'Thông tin về sản phẩm'!$AY$2:$AY$6228),"") -> Gạch POR Ốp_Lát | AH23: =IFERROR(_xlfn.XLOOKUP($C23,'Thông tin về sản phẩm'!$A$2:$A$6228,'Thông tin về sản phẩm'!$AZ$2:$AZ$6228),"")
A24: CERAMIC | B24: 100x200 | C24: 10000310 | D24: 311020COLOUR019 | E24: CER 100x200, 1020COLOUR019, AA | F24: 1020COLOUR019 | G24: MỜ | I24: Sale | J24: 391000 | K24: 312800 | L24: 324530 | M24: 265900 | N24: 277600 | O24: 0.2 | P24: 0.17 | Q24: 📦 Xả kho (CT2 – TB 173) | R24: 252605 | S24: 277600 | T24: 0.35395141 | U24: =IFERROR(_xlfn.XLOOKUP($C24,'Thông tin về sản phẩm'!$A$2:$A$6228,'Thông tin về sản phẩm'!$F$2:$F$6228),"") -> GẠCH, CER 100x200, 1020COLOUR019, Loại AA (L1) | V24: =IFERROR(_xlfn.XLOOKUP($C24,'Thông tin về sản phẩm'!$A$2:$A$6228,'Thông tin về sản phẩm'!$S$2:$S$6228),"") -> ỐP_TƯỜNG | W24: =IFERROR(_xlfn.XLOOKUP($C24,'Thông tin về sản phẩm'!$A$2:$A$6228,'Thông tin về sản phẩm'!$Y$2:$Y$6228),"") -> XANH_LÁ | X24: =IFERROR(_xlfn.XLOOKUP($C24,'Thông tin về sản phẩm'!$A$2:$A$6228,'Thông tin về sản phẩm'!$AA$2:$AA$6228),"") -> ĐẶC_THÙ | Y24: =IFERROR(_xlfn.XLOOKUP($C24,'Thông tin về sản phẩm'!$A$2:$A$6228,'Thông tin về sản phẩm'!$AC$2:$AC$6228),"") -> KHÔNG_HOA_VĂN | Z24: =IFERROR(_xlfn.XLOOKUP($C24,'Thông tin về sản phẩm'!$A$2:$A$6228,'Thông tin về sản phẩm'!$AD$2:$AD$6228),"") -> 0.28 | AA24: =IFERROR(_xlfn.XLOOKUP($C24,'Thông tin về sản phẩm'!$A$2:$A$6228,'Thông tin về sản phẩm'!$I$2:$I$6228),"") -> VIE | AB24: =IFERROR(_xlfn.XLOOKUP($C24,'Thông tin về sản phẩm'!$A$2:$A$6228,'Thông tin về sản phẩm'!$AI$2:$AI$6228),"") -> 200 | AC24: =IFERROR(_xlfn.XLOOKUP($C24,'Thông tin về sản phẩm'!$A$2:$A$6228,'Thông tin về sản phẩm'!$AJ$2:$AJ$6228),"") -> 100 | AD24: =IFERROR(_xlfn.XLOOKUP($C24,'Thông tin về sản phẩm'!$A$2:$A$6228,'Thông tin về sản phẩm'!$AK$2:$AK$6228),"") -> 8 | AE24: =IFERROR(_xlfn.XLOOKUP($C24,'Thông tin về sản phẩm'!$A$2:$A$6228,'Thông tin về sản phẩm'!$AL$2:$AL$6228),"") -> MM | AF24: =IFERROR(_xlfn.XLOOKUP($C24,'Thông tin về sản phẩm'!$A$2:$A$6228,'Thông tin về sản phẩm'!$AM$2:$AM$6228),"") -> NSX | AG24: =IFERROR(_xlfn.XLOOKUP($C24,'Thông tin về sản phẩm'!$A$2:$A$6228,'Thông tin về sản phẩm'!$AY$2:$AY$6228),"") -> Gạch CER Ốp_Tường | AH24: =IFERROR(_xlfn.XLOOKUP($C24,'Thông tin về sản phẩm'!$A$2:$A$6228,'Thông tin về sản phẩm'!$AZ$2:$AZ$6228),"") -> 5. Cơ bản
A25: CERAMIC | B25: 100x200 | C25: 10006307 | D25: 311020ROCK014 | E25: CER 100x200, 1020ROCK014, AA | F25: 1020ROCK014 | G25: MỜ | I25: Sale | J25: 216000 | K25: 172800 | L25: 179280 | M25: 146900 | N25: 153400 | O25: 0.2 | P25: 0.17 | Q25: 📦 Xả kho (CT2 – TB 173) | R25: 139555 | S25: 153400 | T25: 0.35391204 | U25: =IFERROR(_xlfn.XLOOKUP($C25,'Thông tin về sản phẩm'!$A$2:$A$6228,'Thông tin về sản phẩm'!$F$2:$F$6228),"") -> GẠCH, CER 100x200, 1020ROCK014, Loại AA (L1) | V25: =IFERROR(_xlfn.XLOOKUP($C25,'Thông tin về sản phẩm'!$A$2:$A$6228,'Thông tin về sản phẩm'!$S$2:$S$6228),"") -> ỐP_TƯỜNG | W25: =IFERROR(_xlfn.XLOOKUP($C25,'Thông tin về sản phẩm'!$A$2:$A$6228,'Thông tin về sản phẩm'!$Y$2:$Y$6228),"") -> NÂU | X25: =IFERROR(_xlfn.XLOOKUP($C25,'Thông tin về sản phẩm'!$A$2:$A$6228,'Thông tin về sản phẩm'!$AA$2:$AA$6228),"") -> ĐẶC_THÙ | Y25: =IFERROR(_xlfn.XLOOKUP($C25,'Thông tin về sản phẩm'!$A$2:$A$6228,'Thông tin về sản phẩm'!$AC$2:$AC$6228),"") -> VÂN_ĐÁ | Z25: =IFERROR(_xlfn.XLOOKUP($C25,'Thông tin về sản phẩm'!$A$2:$A$6228,'Thông tin về sản phẩm'!$AD$2:$AD$6228),"") -> 0.308 | AA25: =IFERROR(_xlfn.XLOOKUP($C25,'Thông tin về sản phẩm'!$A$2:$A$6228,'Thông tin về sản phẩm'!$I$2:$I$6228),"") -> VIE | AB25: =IFERROR(_xlfn.XLOOKUP($C25,'Thông tin về sản phẩm'!$A$2:$A$6228,'Thông tin về sản phẩm'!$AI$2:$AI$6228),"") -> 200 | AC25: =IFERROR(_xlfn.XLOOKUP($C25,'Thông tin về sản phẩm'!$A$2:$A$6228,'Thông tin về sản phẩm'!$AJ$2:$AJ$6228),"") -> 100 | AD25: =IFERROR(_xlfn.XLOOKUP($C25,'Thông tin về sản phẩm'!$A$2:$A$6228,'Thông tin về sản phẩm'!$AK$2:$AK$6228),"") -> 8 | AE25: =IFERROR(_xlfn.XLOOKUP($C25,'Thông tin về sản phẩm'!$A$2:$A$6228,'Thông tin về sản phẩm'!$AL$2:$AL$6228),"") -> MM | AF25: =IFERROR(_xlfn.XLOOKUP($C25,'Thông tin về sản phẩm'!$A$2:$A$6228,'Thông tin về sản phẩm'!$AM$2:$AM$6228),"") -> MV_ | AG25: =IFERROR(_xlfn.XLOOKUP($C25,'Thông tin về sản phẩm'!$A$2:$A$6228,'Thông tin về sản phẩm'!$AY$2:$AY$6228),"") -> Gạch CER Ốp_Tường | AH25: =IFERROR(_xlfn.XLOOKUP($C25,'Thông tin về sản phẩm'!$A$2:$A$6228,'Thông tin về sản phẩm'!$AZ$2:$AZ$6228),"") -> 5. Cơ bản
A26: CERAMIC | B26: 100x200 | C26: 10006305 | D26: 311020ROCK012 | E26: CER 100x200, 1020ROCK012, AA | F26: 1020ROCK012 | G26: MỜ | I26: Sale | J26: 216000 | K26: 172800 | L26: 179280 | M26: 146900 | N26: 153400 | O26: 0.2 | P26: 0.17 | Q26: 📦 Xả kho (CT2 – TB 173) | R26: 139555 | S26: 153400 | T26: 0.35391204 | U26: =IFERROR(_xlfn.XLOOKUP($C26,'Thông tin về sản phẩm'!$A$2:$A$6228,'Thông tin về sản phẩm'!$F$2:$F$6228),"") -> GẠCH, CER 100x200, 1020ROCK012, Loại AA (L1) | V26: =IFERROR(_xlfn.XLOOKUP($C26,'Thông tin về sản phẩm'!$A$2:$A$6228,'Thông tin về sản phẩm'!$S$2:$S$6228),"") -> ỐP_TƯỜNG | W26: =IFERROR(_xlfn.XLOOKUP($C26,'Thông tin về sản phẩm'!$A$2:$A$6228,'Thông tin về sản phẩm'!$Y$2:$Y$6228),"") -> NÂU | X26: =IFERROR(_xlfn.XLOOKUP($C26,'Thông tin về sản phẩm'!$A$2:$A$6228,'Thông tin về sản phẩm'!$AA$2:$AA$6228),"") -> ĐẶC_THÙ | Y26: =IFERROR(_xlfn.XLOOKUP($C26,'Thông tin về sản phẩm'!$A$2:$A$6228,'Thông tin về sản phẩm'!$AC$2:$AC$6228),"") -> VÂN_ĐÁ | Z26: =IFERROR(_xlfn.XLOOKUP($C26,'Thông tin về sản phẩm'!$A$2:$A$6228,'Thông tin về sản phẩm'!$AD$2:$AD$6228),"") -> 0.308 | AA26: =IFERROR(_xlfn.XLOOKUP($C26,'Thông tin về sản phẩm'!$A$2:$A$6228,'Thông tin về sản phẩm'!$I$2:$I$6228),"") -> VIE | AB26: =IFERROR(_xlfn.XLOOKUP($C26,'Thông tin về sản phẩm'!$A$2:$A$6228,'Thông tin về sản phẩm'!$AI$2:$AI$6228),"") -> 200 | AC26: =IFERROR(_xlfn.XLOOKUP($C26,'Thông tin về sản phẩm'!$A$2:$A$6228,'Thông tin về sản phẩm'!$AJ$2:$AJ$6228),"") -> 100 | AD26: =IFERROR(_xlfn.XLOOKUP($C26,'Thông tin về sản phẩm'!$A$2:$A$6228,'Thông tin về sản phẩm'!$AK$2:$AK$6228),"") -> 8 | AE26: =IFERROR(_xlfn.XLOOKUP($C26,'Thông tin về sản phẩm'!$A$2:$A$6228,'Thông tin về sản phẩm'!$AL$2:$AL$6228),"") -> MM | AF26: =IFERROR(_xlfn.XLOOKUP($C26,'Thông tin về sản phẩm'!$A$2:$A$6228,'Thông tin về sản phẩm'!$AM$2:$AM$6228),"") -> MV_ | AG26: =IFERROR(_xlfn.XLOOKUP($C26,'Thông tin về sản phẩm'!$A$2:$A$6228,'Thông tin về sản phẩm'!$AY$2:$AY$6228),"") -> Gạch CER Ốp_Tường | AH26: =IFERROR(_xlfn.XLOOKUP($C26,'Thông tin về sản phẩm'!$A$2:$A$6228,'Thông tin về sản phẩm'!$AZ$2:$AZ$6228),"") -> 5. Cơ bản
A27: CERAMIC | B27: 100x200 | C27: 10000186 | D27: 311020ROCK002 | E27: CER 100x200, 1020ROCK002, AA | F27: 1020ROCK002 | G27: MỜ | I27: Sale | J27: 216000 | K27: 172800 | L27: 179280 | M27: 146900 | N27: 153400 | O27: 0.2 | P27: 0.17 | Q27: 🔥 Sale tháng (CT1 – TB 169) | R27: 139555 | S27: 153400 | T27: 0.35391204 | U27: =IFERROR(_xlfn.XLOOKUP($C27,'Thông tin về sản phẩm'!$A$2:$A$6228,'Thông tin về sản phẩm'!$F$2:$F$6228),"") -> GẠCH, CER 100x200, 1020ROCK002, Loại AA (L1) | V27: =IFERROR(_xlfn.XLOOKUP($C27,'Thông tin về sản phẩm'!$A$2:$A$6228,'Thông tin về sản phẩm'!$S$2:$S$6228),"") -> ỐP_TƯỜNG | W27: =IFERROR(_xlfn.XLOOKUP($C27,'Thông tin về sản phẩm'!$A$2:$A$6228,'Thông tin về sản phẩm'!$Y$2:$Y$6228),"") -> KEM | X27: =IFERROR(_xlfn.XLOOKUP($C27,'Thông tin về sản phẩm'!$A$2:$A$6228,'Thông tin về sản phẩm'!$AA$2:$AA$6228),"") -> ĐẶC_THÙ | Y27: =IFERROR(_xlfn.XLOOKUP($C27,'Thông tin về sản phẩm'!$A$2:$A$6228,'Thông tin về sản phẩm'!$AC$2:$AC$6228),"") -> VÂN_ĐÁ | Z27: =IFERROR(_xlfn.XLOOKUP($C27,'Thông tin về sản phẩm'!$A$2:$A$6228,'Thông tin về sản phẩm'!$AD$2:$AD$6228),"") -> 0.308 | AA27: =IFERROR(_xlfn.XLOOKUP($C27,'Thông tin về sản phẩm'!$A$2:$A$6228,'Thông tin về sản phẩm'!$I$2:$I$6228),"") -> VIE | AB27: =IFERROR(_xlfn.XLOOKUP($C27,'Thông tin về sản phẩm'!$A$2:$A$6228,'Thông tin về sản phẩm'!$AI$2:$AI$6228),"") -> 200 | AC27: =IFERROR(_xlfn.XLOOKUP($C27,'Thông tin về sản phẩm'!$A$2:$A$6228,'Thông tin về sản phẩm'!$AJ$2:$AJ$6228),"") -> 100 | AD27: =IFERROR(_xlfn.XLOOKUP($C27,'Thông tin về sản phẩm'!$A$2:$A$6228,'Thông tin về sản phẩm'!$AK$2:$AK$6228),"") -> 8 | AE27: =IFERROR(_xlfn.XLOOKUP($C27,'Thông tin về sản phẩm'!$A$2:$A$6228,'Thông tin về sản phẩm'!$AL$2:$AL$6228),"") -> MM | AF27: =IFERROR(_xlfn.XLOOKUP($C27,'Thông tin về sản phẩm'!$A$2:$A$6228,'Thông tin về sản phẩm'!$AM$2:$AM$6228),"") -> MV_ | AG27: =IFERROR(_xlfn.XLOOKUP($C27,'Thông tin về sản phẩm'!$A$2:$A$6228,'Thông tin về sản phẩm'!$AY$2:$AY$6228),"") -> Gạch CER Ốp_Tường | AH27: =IFERROR(_xlfn.XLOOKUP($C27,'Thông tin về sản phẩm'!$A$2:$A$6228,'Thông tin về sản phẩm'!$AZ$2:$AZ$6228),"") -> 4. Tiềm năng
A28: CERAMIC | B28: 100x200 | C28: 10000306 | D28: 311020COLOUR002 | E28: CER 100x200, 1020COLOUR002, AA | F28: 1020COLOUR002 | G28: MỜ | I28: Sale | J28: 391000 | K28: 312800 | L28: 324530 | M28: 265900 | N28: 277600 | O28: 0.2 | P28: 0.17 | Q28: 📦 Xả kho (CT2 – TB 173) | R28: 252605 | S28: 277600 | T28: 0.35395141 | U28: =IFERROR(_xlfn.XLOOKUP($C28,'Thông tin về sản phẩm'!$A$2:$A$6228,'Thông tin về sản phẩm'!$F$2:$F$6228),"") -> GẠCH, CER 100x200, 1020COLOUR002, Loại AA (L1) | V28: =IFERROR(_xlfn.XLOOKUP($C28,'Thông tin về sản phẩm'!$A$2:$A$6228,'Thông tin về sản phẩm'!$S$2:$S$6228),"") -> ỐP_TƯỜNG | W28: =IFERROR(_xlfn.XLOOKUP($C28,'Thông tin về sản phẩm'!$A$2:$A$6228,'Thông tin về sản phẩm'!$Y$2:$Y$6228),"") -> CAM | X28: =IFERROR(_xlfn.XLOOKUP($C28,'Thông tin về sản phẩm'!$A$2:$A$6228,'Thông tin về sản phẩm'!$AA$2:$AA$6228),"") -> ĐẶC_THÙ | Y28: =IFERROR(_xlfn.XLOOKUP($C28,'Thông tin về sản phẩm'!$A$2:$A$6228,'Thông tin về sản phẩm'!$AC$2:$AC$6228),"") -> KHÔNG_HOA_VĂN | Z28: =IFERROR(_xlfn.XLOOKUP($C28,'Thông tin về sản phẩm'!$A$2:$A$6228,'Thông tin về sản phẩm'!$AD$2:$AD$6228),"") -> 0.303 | AA28: =IFERROR(_xlfn.XLOOKUP($C28,'Thông tin về sản phẩm'!$A$2:$A$6228,'Thông tin về sản phẩm'!$I$2:$I$6228),"") -> VIE | AB28: =IFERROR(_xlfn.XLOOKUP($C28,'Thông tin về sản phẩm'!$A$2:$A$6228,'Thông tin về sản phẩm'!$AI$2:$AI$6228),"") -> 200 | AC28: =IFERROR(_xlfn.XLOOKUP($C28,'Thông tin về sản phẩm'!$A$2:$A$6228,'Thông tin về sản phẩm'!$AJ$2:$AJ$6228),"") -> 100 | AD28: =IFERROR(_xlfn.XLOOKUP($C28,'Thông tin về sản phẩm'!$A$2:$A$6228,'Thông tin về sản phẩm'!$AK$2:$AK$6228),"") -> 8 | AE28: =IFERROR(_xlfn.XLOOKUP($C28,'Thông tin về sản phẩm'!$A$2:$A$6228,'Thông tin về sản phẩm'!$AL$2:$AL$6228),"") -> MM | AF28: =IFERROR(_xlfn.XLOOKUP($C28,'Thông tin về sản phẩm'!$A$2:$A$6228,'Thông tin về sản phẩm'!$AM$2:$AM$6228),"") -> NSX | AG28: =IFERROR(_xlfn.XLOOKUP($C28,'Thông tin về sản phẩm'!$A$2:$A$6228,'Thông tin về sản phẩm'!$AY$2:$AY$6228),"") -> Gạch CER Ốp_Tường | AH28: =IFERROR(_xlfn.XLOOKUP($C28,'Thông tin về sản phẩm'!$A$2:$A$6228,'Thông tin về sản phẩm'!$AZ$2:$AZ$6228),"") -> 5. Cơ bản
A29: CERAMIC | B29: 100x200 | C29: 10000308 | D29: 311020COLOUR012 | E29: CER 100x200, 1020COLOUR012, AA | F29: 1020COLOUR012 | G29: MỜ | I29: Sale | J29: 391000 | K29: 312800 | L29: 324530 | M29: 265900 | N29: 277600 | O29: 0.2 | P29: 0.17 | Q29: 🔥 Sale tháng (CT1 – TB 169) | R29: 252605 | S29: 277600 | T29: 0.35395141 | U29: =IFERROR(_xlfn.XLOOKUP($C29,'Thông tin về sản phẩm'!$A$2:$A$6228,'Thông tin về sản phẩm'!$F$2:$F$6228),"") -> GẠCH, CER 100x200, 1020COLOUR012, Loại AA (L1) | V29: =IFERROR(_xlfn.XLOOKUP($C29,'Thông tin về sản phẩm'!$A$2:$A$6228,'Thông tin về sản phẩm'!$S$2:$S$6228),"") -> ỐP_TƯỜNG | W29: =IFERROR(_xlfn.XLOOKUP($C29,'Thông tin về sản phẩm'!$A$2:$A$6228,'Thông tin về sản phẩm'!$Y$2:$Y$6228),"") -> XANH_DƯƠNG | X29: =IFERROR(_xlfn.XLOOKUP($C29,'Thông tin về sản phẩm'!$A$2:$A$6228,'Thông tin về sản phẩm'!$AA$2:$AA$6228),"") -> ĐẶC_THÙ | Y29: =IFERROR(_xlfn.XLOOKUP($C29,'Thông tin về sản phẩm'!$A$2:$A$6228,'Thông tin về sản phẩm'!$AC$2:$AC$6228),"") -> KHÔNG_HOA_VĂN | Z29: =IFERROR(_xlfn.XLOOKUP($C29,'Thông tin về sản phẩm'!$A$2:$A$6228,'Thông tin về sản phẩm'!$AD$2:$AD$6228),"") -> 0.301 | AA29: =IFERROR(_xlfn.XLOOKUP($C29,'Thông tin về sản phẩm'!$A$2:$A$6228,'Thông tin về sản phẩm'!$I$2:$I$6228),"") -> VIE | AB29: =IFERROR(_xlfn.XLOOKUP($C29,'Thông tin về sản phẩm'!$A$2:$A$6228,'Thông tin về sản phẩm'!$AI$2:$AI$6228),"") -> 200 | AC29: =IFERROR(_xlfn.XLOOKUP($C29,'Thông tin về sản phẩm'!$A$2:$A$6228,'Thông tin về sản phẩm'!$AJ$2:$AJ$6228),"") -> 100 | AD29: =IFERROR(_xlfn.XLOOKUP($C29,'Thông tin về sản phẩm'!$A$2:$A$6228,'Thông tin về sản phẩm'!$AK$2:$AK$6228),"") -> 8 | AE29: =IFERROR(_xlfn.XLOOKUP($C29,'Thông tin về sản phẩm'!$A$2:$A$6228,'Thông tin về sản phẩm'!$AL$2:$AL$6228),"") -> MM | AF29: =IFERROR(_xlfn.XLOOKUP($C29,'Thông tin về sản phẩm'!$A$2:$A$6228,'Thông tin về sản phẩm'!$AM$2:$AM$6228),"") -> NSX | AG29: =IFERROR(_xlfn.XLOOKUP($C29,'Thông tin về sản phẩm'!$A$2:$A$6228,'Thông tin về sản phẩm'!$AY$2:$AY$6228),"") -> Gạch CER Ốp_Tường | AH29: =IFERROR(_xlfn.XLOOKUP($C29,'Thông tin về sản phẩm'!$A$2:$A$6228,'Thông tin về sản phẩm'!$AZ$2:$AZ$6228),"") -> 4. Tiềm năng
A30: CERAMIC | B30: 100x200 | C30: 10000307 | D30: 311020COLOUR006 | E30: CER 100x200, 1020COLOUR006, AA | F30: 1020COLOUR006 | G30: MỜ | I30: Sale | J30: 391000 | K30: 312800 | L30: 324530 | M30: 265900 | N30: 277600 | O30: 0.2 | P30: 0.17 | Q30: 🔥 Sale tháng (CT1 – TB 169) | R30: 252605 | S30: 277600 | T30: 0.35395141 | U30: =IFERROR(_xlfn.XLOOKUP($C30,'Thông tin về sản phẩm'!$A$2:$A$6228,'Thông tin về sản phẩm'!$F$2:$F$6228),"") -> GẠCH, CER 100x200, 1020COLOUR006, Loại AA (L1) | V30: =IFERROR(_xlfn.XLOOKUP($C30,'Thông tin về sản phẩm'!$A$2:$A$6228,'Thông tin về sản phẩm'!$S$2:$S$6228),"") -> ỐP_TƯỜNG | W30: =IFERROR(_xlfn.XLOOKUP($C30,'Thông tin về sản phẩm'!$A$2:$A$6228,'Thông tin về sản phẩm'!$Y$2:$Y$6228),"") -> VÀNG | X30: =IFERROR(_xlfn.XLOOKUP($C30,'Thông tin về sản phẩm'!$A$2:$A$6228,'Thông tin về sản phẩm'!$AA$2:$AA$6228),"") -> ĐẶC_THÙ | Y30: =IFERROR(_xlfn.XLOOKUP($C30,'Thông tin về sản phẩm'!$A$2:$A$6228,'Thông tin về sản phẩm'!$AC$2:$AC$6228),"") -> KHÔNG_HOA_VĂN | Z30: =IFERROR(_xlfn.XLOOKUP($C30,'Thông tin về sản phẩm'!$A$2:$A$6228,'Thông tin về sản phẩm'!$AD$2:$AD$6228),"") -> 0.302 | AA30: =IFERROR(_xlfn.XLOOKUP($C30,'Thông tin về sản phẩm'!$A$2:$A$6228,'Thông tin về sản phẩm'!$I$2:$I$6228),"") -> VIE | AB30: =IFERROR(_xlfn.XLOOKUP($C30,'Thông tin về sản phẩm'!$A$2:$A$6228,'Thông tin về sản phẩm'!$AI$2:$AI$6228),"") -> 200 | AC30: =IFERROR(_xlfn.XLOOKUP($C30,'Thông tin về sản phẩm'!$A$2:$A$6228,'Thông tin về sản phẩm'!$AJ$2:$AJ$6228),"") -> 100 | AD30: =IFERROR(_xlfn.XLOOKUP($C30,'Thông tin về sản phẩm'!$A$2:$A$6228,'Thông tin về sản phẩm'!$AK$2:$AK$6228),"") -> 8 | AE30: =IFERROR(_xlfn.XLOOKUP($C30,'Thông tin về sản phẩm'!$A$2:$A$6228,'Thông tin về sản phẩm'!$AL$2:$AL$6228),"") -> MM | AF30: =IFERROR(_xlfn.XLOOKUP($C30,'Thông tin về sản phẩm'!$A$2:$A$6228,'Thông tin về sản phẩm'!$AM$2:$AM$6228),"") -> NSX | AG30: =IFERROR(_xlfn.XLOOKUP($C30,'Thông tin về sản phẩm'!$A$2:$A$6228,'Thông tin về sản phẩm'!$AY$2:$AY$6228),"") -> Gạch CER Ốp_Tường | AH30: =IFERROR(_xlfn.XLOOKUP($C30,'Thông tin về sản phẩm'!$A$2:$A$6228,'Thông tin về sản phẩm'!$AZ$2:$AZ$6228),"") -> 4. Tiềm năng
A31: CERAMIC | B31: 100x200 | C31: 10000068 | D31: 311020COLOUR003 | E31: CER 100x200, 1020COLOUR003, AA | F31: 1020COLOUR003 | G31: BÓNG | I31: Sale | J31: 391000 | K31: 312800 | L31: 324530 | M31: 265900 | N31: 277600 | O31: 0.2 | P31: 0.17 | Q31: 📦 Xả kho (CT2 – TB 173) | R31: 252605 | S31: 277600 | T31: 0.35395141 | U31: =IFERROR(_xlfn.XLOOKUP($C31,'Thông tin về sản phẩm'!$A$2:$A$6228,'Thông tin về sản phẩm'!$F$2:$F$6228),"") -> GẠCH, CER 100x200, 1020COLOUR003, Loại AA (L1) | V31: =IFERROR(_xlfn.XLOOKUP($C31,'Thông tin về sản phẩm'!$A$2:$A$6228,'Thông tin về sản phẩm'!$S$2:$S$6228),"") -> ỐP_TƯỜNG | W31: =IFERROR(_xlfn.XLOOKUP($C31,'Thông tin về sản phẩm'!$A$2:$A$6228,'Thông tin về sản phẩm'!$Y$2:$Y$6228),"") -> TRẮNG | X31: =IFERROR(_xlfn.XLOOKUP($C31,'Thông tin về sản phẩm'!$A$2:$A$6228,'Thông tin về sản phẩm'!$AA$2:$AA$6228),"") -> ĐẶC_THÙ | Y31: =IFERROR(_xlfn.XLOOKUP($C31,'Thông tin về sản phẩm'!$A$2:$A$6228,'Thông tin về sản phẩm'!$AC$2:$AC$6228),"") -> KHÔNG_HOA_VĂN | Z31: =IFERROR(_xlfn.XLOOKUP($C31,'Thông tin về sản phẩm'!$A$2:$A$6228,'Thông tin về sản phẩm'!$AD$2:$AD$6228),"") -> 0.287 | AA31: =IFERROR(_xlfn.XLOOKUP($C31,'Thông tin về sản phẩm'!$A$2:$A$6228,'Thông tin về sản phẩm'!$I$2:$I$6228),"") -> VIE | AB31: =IFERROR(_xlfn.XLOOKUP($C31,'Thông tin về sản phẩm'!$A$2:$A$6228,'Thông tin về sản phẩm'!$AI$2:$AI$6228),"") -> 200 | AC31: =IFERROR(_xlfn.XLOOKUP($C31,'Thông tin về sản phẩm'!$A$2:$A$6228,'Thông tin về sản phẩm'!$AJ$2:$AJ$6228),"") -> 100 | AD31: =IFERROR(_xlfn.XLOOKUP($C31,'Thông tin về sản phẩm'!$A$2:$A$6228,'Thông tin về sản phẩm'!$AK$2:$AK$6228),"") -> 8 | AE31: =IFERROR(_xlfn.XLOOKUP($C31,'Thông tin về sản phẩm'!$A$2:$A$6228,'Thông tin về sản phẩm'!$AL$2:$AL$6228),"") -> MM | AF31: =IFERROR(_xlfn.XLOOKUP($C31,'Thông tin về sản phẩm'!$A$2:$A$6228,'Thông tin về sản phẩm'!$AM$2:$AM$6228),"") -> NSX | AG31: =IFERROR(_xlfn.XLOOKUP($C31,'Thông tin về sản phẩm'!$A$2:$A$6228,'Thông tin về sản phẩm'!$AY$2:$AY$6228),"") -> Gạch CER Ốp_Tường | AH31: =IFERROR(_xlfn.XLOOKUP($C31,'Thông tin về sản phẩm'!$A$2:$A$6228,'Thông tin về sản phẩm'!$AZ$2:$AZ$6228),"") -> 5. Cơ bản
